Workbook
Name concepto.1087: #REF!
Name concepto.1087: #REF!
Name concepto.1087: #REF!
Name concepto.1087: #REF!
Name concepto.1087: #REF!
Name concepto.1087: #REF!
Name concepto.1087: #REF!
Name concepto.1087: #REF!
Name concepto.1087: #REF!
Name concepto.1087: #REF!
Name concepto.1087: #REF!
Name concepto1004: #REF!
Name concepto1004: #REF!
Name concepto1004: #REF!
Name concepto1004: #REF!
Name concepto1004: #REF!
Name concepto1004: #REF!
Name concepto1004: #REF!
Name concepto1004: #REF!
Name concepto1004: #REF!
Name concepto1004: #REF!
Name concepto1004: #REF!
Name concepto1004.casillero: #REF!
Name concepto1004.casillero: #REF!
Name concepto1004.casillero: #REF!
Name concepto1004.casillero: #REF!
Name concepto1004.casillero: #REF!
Name concepto1004.casillero: #REF!
Name concepto1004.casillero: #REF!
Name concepto1004.casillero: #REF!
Name concepto1004.casillero: #REF!
Name concepto1004.casillero: #REF!
Name concepto1004.casillero: #REF!
Name concepto1004.error1: #REF!
Name concepto1004.error1: #REF!
Name concepto1004.error1: #REF!
Name concepto1004.error1: #REF!
Name concepto1004.error1: #REF!
Name concepto1004.error1: #REF!
Name concepto1004.error1: #REF!
Name concepto1004.error1: #REF!
Name concepto1004.error1: #REF!
Name concepto1004.error1: #REF!
Name concepto1004.error1: #REF!
Name concepto1004.error2: #REF!
Name concepto1004.error2: #REF!
Name concepto1004.error2: #REF!
Name concepto1004.error2: #REF!
Name concepto1004.error2: #REF!
Name concepto1004.error2: #REF!
Name concepto1004.error2: #REF!
Name concepto1004.error2: #REF!
Name concepto1004.error2: #REF!
Name concepto1004.error2: #REF!
Name concepto1004.error2: #REF!
Name concepto1004.validacion1: #REF!
Name concepto1004.validacion1: #REF!
Name concepto1004.validacion1: #REF!
Name concepto1004.validacion1: #REF!
Name concepto1004.validacion1: #REF!

Sheet REVEPYMES 11,12.23,27,29,34,33 
B3: Sección 27
B4: Deterioro del Valor de los Activos
B6: Información a revelar
B7: 27.32 Una entidad revelará, para cada clase de activos indicada en el párrafo 27.33, la
B8: siguiente información:
B9: (a) El importe de las pérdidas por deterioro del valor reconocidas en resultados
B10: durante el periodo y la partida o partidas del estado del resultado integral
B11: (y del estado de resultados, si se presenta) en las que esas pérdidas por
B12: deterioro del valor estén incluidas.
B13: (b) El importe de las reversiones de pérdidas por deterioro del valor
B14: reconocidas en resultados durante el periodo y la partida o partidas del
B15: estado del resultado integral (y del estado de resultados, si se presenta) en
... B457: todos las obligaciones con relacionadas deben tener la confirmaciones

Sheet EXPLICACION MARCA
A1: EXPLICACION DE MARCA
A2: √= Verificado y está conforme con la revisión, Cotejado con documento (físico)
A5: = verificado y no está conforme, revisar 1 error
A7: X= error, No cumple con todos los requisitos
A9: Ø= Información incorrecta
A11: = Falta información
A13: S= Solicitud de confirmación enviada
A15: SI= Solicitud de confirmación recibida inconforme
A17: SIA= Solicitud de confirmación recibida inconforme pero aclarada
A19: SC= Solicitud de confirmación recibida conforme
A21: ∑= Sumatoria, totalizado
A23: €= Conciliado
... A47: V = Ver hoja

Sheet 12RATIOS FINANCIEROS 
A6: MATRIZ DE REVISION ANALITICA
A8: CLIENTE: | H8: RATIOS
A9: PERIODO:
A10: CUESTIONARIO:
A11: REVISADO: | D11: ANTERIOR | E11: ACTUAL
A12: Elaborado por: | C12: ACTIVO CORRIENTE | D12: =SUM('4 BG101'!D11:D14) -> 21075.33 | E12: =SUM('4 BG101'!M11:M13) -> 0
C13: PASIVO CORRIENTE | D13: =SUM('4 BG101'!D30:D36) -> 502.05 | E13: =SUM('4 BG101'!M30:M36) -> 0
A14: DENOMINACION DEL RATIO | B14: FORMULA | C14: INTERPRETACIÓN | D14: RATIOS RESULTADOS DEL PERIODO | F14: COMENTARIOS | G14: EVALUACION DEL RIESGO
D15: AÑO ANTERIOR | E15: AÑO ACTUAL | G15: ALTO | H15: MODERADO | I15: BAJO
A16: Corriente | B16: Activo corriente/ pasivo coriente | C16: La empresa cuenta por cada | D16: =+D12/D13 -> 41.978548 | E16: =+E12/E13 -> #DIV/0!
A17: Prueba acida | B17: Activo corriente - nventaios / Pasivo corriente | C17: La empresa cuenta por cada S/ 1.00 de deuda corriente | D17: =+(D12-'4 BG101'!D14)/D13 -> 41.978548 | E17: =+(E12-'4 BG101'!M14)/E13 -> #DIV/0!
A18: Liquidez inmediata | B18: Efectivo y equivalente de efectivo / Pasivo corriente | C18: La empresa cuenta por cada S/ 1.00 de deuda corriente | D18: =+'4 BG101'!D11/'12RATIOS FINANCIEROS '!D13 -> 41.978548 | E18: =+'4 BG101'!M11/'12RATIOS FINANCIEROS '!E13 -> #DIV/0!
A19: capital de trabajo | B19: Activo corriente - pasivo corriente | C19: La empresa cuenta con como capital de trabajo, para poder operar, en el sector comercial monto no razonable ya que si comparamos con el capital invertido por los socios , existe una desproporción entre la inversión destinado al capital de trabajo y la inversión en activos de propiedad planta y equipo | D19: =+D12-D13 -> 20573.28 | E19: =+E12-E13 -> 0
A20: Periodo pro medio de cobranza | B20: Cuentas por cobrar (x) 360 Días/ Ventas anuales | C20: El tiempo que tarda en convertirse en efectivo las cuentas por cobrar es de 50 días | D20: =(+'4 BG101'!D12*360)/'5 PG101'!D19 -> 0 | E20: =(+'4 BG101'!M12*360)/'5 PG101'!L19 -> #DIV/0!
A21: Rotación de cuentas por cobrar | B21: Ventas/ Cuentas por cobrar | C21: La cuentas por cobrar circulan 7 veces durante el año comercial, o lo que significa que, se convierten en efectivo en promedio de 7 veces al año, estándar ideal en empresas comercial la rotación debe ser mensual | D21: =+'5 PG101'!D19/'4 BG101'!D12 -> #DIV/0! | E21: =+'5 PG101'!L19/'4 BG101'!M12 -> #DIV/0!
A22: Rotación de inventario | B22: Inventario promedio * 360 dias / costo de ventas | C22: Esto quiere decir que los inventarios se venden cada 172 días, lo que de muestra una baja o lenta rotación de los inventarios, en nuestro caso 2.28 veces al año. A mayor rotación mayor movilidad del capital de trabajo invertido en nventarios y más rápida es la generación de utilidades | E22: =((+'4 BG101'!D14+'4 BG101'!M14)/2)/360 -> 0
B23: 2,398.500 X 360 / 5,47 4,000 = 157.7 Días 360 Días / 157,7 = 2.28 veces al año
B24: (Costo de ventas / inventario promedio) x 2 (5,474,000 / 4,797,000) X 2 =1.14 X 2=2.28 veces | E24: =SUM('5 PG101'!L22:L28)/((+'4 BG101'!D14+'4 BG101'!M14)/2) -> #DIV/0!
A25: Período promedio de pago a proveedores | B25: Cuentas por pagar (promeio) x 360 días/ compras a proveedores 3,025,952 X 360 / 9,552,000 = 114.04 Días 360 / 114.04 = 3.16 Veces al año | E25: =(+'4 BG101'!D30+'4 BG101'!M30)/2*360/'5 PG101'!L22 -> #DIV/0!

Sheet 11Materialidad SUM
D1: PAPELES DE TRABAJO 3ANG ADMINISTRACIÓN DE NEGOCIOS GERENCIALES CÍA. LTDA.
D3: =+'4 BG101'!B2 -> TABACALERA MENHURSA S.A.
D5: A/T 31 DICIEMBRE DEL 2023
D7: CÁLCULO DE LA MATERIALIDAD PLANEADA
C10: ELABORADO POR: | D10: =+'28 Certif del equipo (2)'!C22 -> Ing. Maria Elizabeth Palacios | J10: FECHA: | L10: 44768
C11: SUPERVISADO POR: | D11: Roy Cisneros | J11: FECHA: | L11: =+L10+2 -> 44770
A13: AAA | C13: Objetivo: | D13: Tener una seguridad alta, aunque no absoluta de que los estados financieros no contengan errores o irregularidades importantes.
A15: AAAA | C15: Naturaleza | D15: La materialidad se refiere a la magnitud o a la naturaleza de un error, que a la luz de las circunstancias prevalecientes, podría cambiar o influenciar en el juicio de un usuario razonable de los estados financieros.
A16: AAAA | D16: La materialidad es una función no sólo de la magnitud de un error, sino también de la naturaleza del error. Dependiendo de las circunstancias los errores de las cantidades relativamente pequeñas pueden tener un impacto material o importante en los estados financieros.
A17: AAAA | D17: Nuestra apreciación de lo que es material es crucial para todo el proceso de auditoria, desde el principio hasta el final.
B19: 1 | C19: Materialidad Sobre los Activos | I19: 3 | J19: Materialidad Sobre los Ingresos | L19: =+'5 PG101'!L19 -> 0
D20: Total Activos | F20: =+'4 BG101'!M27 -> 0 | J20: % | L20: 0.01
D21: % | F21: 0.01 | L21: =+L20*L19 -> 0
F22: =+F20*F21 -> 0
B23: 2 | C23: Materialidad Sobre los pasivos | I23: 4 | J23: Materialidad Sobre los Gastos | L23: =+'5 PG101'!L41 -> 0
D24: Total Pasivos | F24: =+'4 BG101'!M46 -> 0 | J24: % | L24: 0.01
D25: % | F25: 0.01 | L25: =+L23*L24 -> 0
F26: =+F25*F24 -> 0
I27: 1 | J27: =+C19 -> Materialidad Sobre los Activos | L27: =+F22 -> 0
B28: 5 | C28: Materialidad Sobre Capital de Trabajo | I28: 2 | J28: =+C23 -> Materialidad Sobre los pasivos | L28: =+F26 -> 0
D29: Activo Corriente | F29: =SUM('4 BG101'!M11:M14) -> 0 | I29: 3 | J29: =+J19 -> Materialidad Sobre los Ingresos | L29: =+L21 -> 0
D30: (-) Pasivo Corriente | F30: =SUM('4 BG101'!M30:M36) -> 0 | I30: 4 | J30: =+J23 -> Materialidad Sobre los Gastos | L30: =+L25 -> 0
D31: Cap. Trab | F31: =+F29-F30 -> 0 | I31: 5 | J31: =+C28 -> Materialidad Sobre Capital de Trabajo | L31: =+F33 -> 0
D32: % | F32: 0.01
F33: =+F31*F32 -> 0 | J33: Materialidad Planeada | L33: =SUM(L27:L31) -> 0
B35: 6 | C35: Resultados antes de impuestos | F35: =+'5 PG101'!L42 -> 0 | K35: Sobre el Activo | L35: 0.03
J38: Activo | K38: =+F20 -> 0 | L38: =+K38*L35 -> 0
D42: Abreviatura
C43: MP: | D43: Materialidad de Planeación | G43: Emi: | H43: Error Mínimo
C44: ET: | D44: Error Tolerable o Importancia Relativa del Desempeño | G44: RDA: | H44: Resumen de Diferencias de Auditoría
C47: BENCHMARKING O BASE DE REFERENCIA | D47: PORCENTAJE PARA DETERMINAR EL NIVEL DE MATERIALIDAD
D48: FIRMA 1 | E48: FIRMA 2 | F48: FIRMA 3 | G48: FIRMA 4 | H48: FIRMA 5 | I48: FIRMA 6
C49: Resultados antes de impuestos Listados en bolsa | D49: 5% a 10% | E49: 5% a 10% | F49: 3% a 10% | G49: 3% a 10% | H49: 5% a 8% | I49: 5% a 10%
C50: Resultados antes de impuestos No listados en bolsa | D50: 5% a 10% | E50: 5% a 10% | F50: 3% a 10% | G50: 3% a 10% | H50: 5% a 10% | I50: Hasta 10%
C51: Utilidad bruta Listados en bolsa | D51: Hasta2.5% | E51: 0 | F51: 0 | G51: 3% a 10% | H51: 1 a2% | I51: Juicio del Auditor
C52: Utilidad bruta No listados en bolsa | D52: Hasta3.5% | E52: 0 | F52: 0 | G52: 3% a 10% | H52: 1%a4% | I52: Juicio del Auditor
C53: Activos netos Listados en bolsa | D53: 0.5%a 1% | E53: 0.5%a 1% | F53: 2%a5% | G53: 3% a 10% | H53: 1%a2% | I53: Hasta3%
C54: Activos netos No Listados en bolsa | D54: 1.75a2% | E54: 0.5% a 1% | F54: 2% a 5% | G54: 3% to 10% | H54: 1% a 5% | I54: Hasta3%
C55: Ingresos Listados en bolsa | D55: Hasta 1% | E55: 0.5%a2% | F55: 0.5%a 2% | G55: 0.5%a3% | H55: 0.5% a 1% | I55: 0.8%a5% En escala móvil
C56: Ingresos No istados en bolsa | D56: Hasta2% | E56: 0.5%a2% | F56: 0.5%a 2% | G56: 0.5%a3% | H56: 0.5%a2% | I56: 0.8%a5% En escala móvil
...

Sheet 31 lavado  de activos 
A2: ¿¿¿¿ | C2: ASUNTOS REQUERIDOS POR LA LEY ORGÁNICA DE PREVENCIÓN, DETECCIÓN Y ERRADICACIÓN DEL DELITO DE LAVADO DE ACTIVOS Y DEL FINANCIAMIENTO DE DELITOS.
C4: A los Accionistas de:
C5: INMCAMPSA S.A.
C7: Santo Domingo, Ecuador
S8: =+'OPINION pymes con anexo '!I72 -> Agosto, 18 del 2023
A9: ¿¿¿¿¿¿¿¿¿ | C9: Hemos auditado los Estados Financieros por el período terminado al 31 de diciembre del 2021 y con fecha 18 de abril del 2022 emitimos el informe de auditoría de la compañía INMCAMPSA S.A., Según lo establecido en la LEY DE PREVENCIÓN, DETECCIÓN Y ERRADICACIÓN DEL DELITO DE LAVADO DE ACTIVOS Y DEL FINANCIAMIENTO DE DELITO, debemos verificar el cumplimiento de lo previsto en esta norma respecto a las políticas, procedimientos y mecanismos implementados por el sujeto obligado para la prevención del lavado de activos, el financiamiento del terrorismo y otros delitos, valorar su eficacia operativa y proponer, de ser el caso, eventuales rectificaciones o mejoras.
A11: ¿¿¿¿¿¿ | C11: 1 | D11: Los sujetos obligados deben contar con políticas y procedimientos de control para prevenir el lavado de activos, el financiamiento del terrorismo y otros delitos de conformidad con lo establecido en la presente norma; y, adoptar medidas de control apropiadas y suficientes, orientadas a evitar que puedan ser utilizados como instrumentos para realizar actividades vinculadas al lavado de activos y/o al financiamiento del terrorismo y otros delitos.
A13: ¿¿ | C13: 2 | D13: Las políticas que adopta la compañía para prevenir el lavado de activos, el financiamiento del terrorismo y otros delitos, cumple con los siguientes parámetros:
A15: ¿¿ | D15: • | E15: Las políticas y procedimientos incorporados le permitan administrar, evaluar y mitigar con eficacia los riesgos que se hayan identificado.
A16: ¿ | D16: • | E16: Abarca toda clase de productos o servicios que ofrece la compañía.
A17: ¿¿¿¿ | D17: • | E17: Asegura que los miembros de la compañía tengan el debido conocimiento, acatamiento y aplicación de las normativas legales y reglamentarias relacionadas con la prevención de lavado de activos y el financiamiento del terrorismo y otros delitos.
A18: ¿¿ | D18: • | E18: Minimiza el grado de exposición inherente al lavado de activos y al financiamiento del terrorismo y otros delitos.
A19: ¿¿ | D19: • | E19: Establece políticas de debida diligencia según el riesgo que la misma compañía ha identificado.
A20: ¿¿¿ | D20: • | E20: Garantiza la reserva y confidencialidad de la información reportada, conforme lo previsto en la Ley de Prevención, Detección y Erradicación del Delito de Lavado de Activos y del Financiamiento de Delitos.
A22: ¿¿ | C22: 3 | D22: Los procedimientos de prevención para el lavado de activos, el financiamiento del terrorismo y otros delitos, adoptados por la compañía le permiten:
A24: ¿¿¿ | D24: • | E24: Identificar al cliente, conocer y verificar su información con el objeto de establecer el perfil, y determinar si el volumen de operaciones guardan relación con la información por éste proporcionada.
A25: ¿¿¿ | D25: • | E25: Comunicar a la Unidad de Análisis Financiero y Económico de la existencia de las transacciones y operaciones económicas que superen el umbral en los términos señalados en la ley.
A26: ¿¿¿ | D26: • | E26: Detectar operaciones o transacciones económicas inusuales e injustificadas, para reportarlas oportunamente y con los sustentos del caso a la Unidad de Análisis Financiero y Económico (UAFE).
A27: ¿¿ | D27: • | E27: Atender los requerimientos de información formulados por autoridades competentes.
A29: ¿¿¿¿¿ | C29: 4 | D29: Los representantes legales o administradores, oficiales de cumplimiento, socios y empleados, están obligados a guardar reserva y confidencialidad respecto de las operaciones que llegan a su conocimiento en el ejercicio de sus funciones. Expresamente se les prohíbe informar de cualquier notificación que hubieren hecho a las autoridades competentes.
A31: ¿¿¿ | C31: 5 | D31: El Manual de Prevención establece las políticas y los procedimientos de control que adopta la compañía y dispone cómo deben operar los mecanismos de prevención establecen los procedimientos :
A33: ¿¿ | D33: • | E33: Implementa la vinculación de nuevos clientes, así como confirma y actualiza la información aportada por los clientes antiguos.
A34: ¿¿ | D34: • | E34: Conserva y protege los registros operativos y documentos relacionados con los clientes y aquellos documentos que sean solicitados por las autoridades.
A35: ¿¿ | D35: • | E35: Define los canales de comunicación e instancias de reporte entre el oficial de cumplimiento y demás áreas de la compañía.
A36: ¿ | D36: • | E36: Atiende oportunamente los reportes periódicos de acuerdo a la ley.
A37: ¿¿ | D37: • | E37: Detecta señales de alerta de acuerdo a la naturaleza de los productos y servicios que ofrece la compañía.
A38: ¿ | D38: • | E38: Cumple las políticas de debidas diligencias que adopte al sujeto obligado.
A39: ¿¿¿ | D39: • | E39: Establece el sistema de prevención de riesgos que mide de forma cualitativa las probabilidades y los posibles impactos de riesgo que tiene cada cliente, operación o transacción dentro del giro de negocio de la organización.
A40: ¿¿ | C40: 6 | D40: El manual debe ser conocido por todo el personal y puede ser actualizado, en caso de requerirlo la compañía.
A42: ¿¿¿¿ | C42: 7 | D42: La compañía al inicio de la relación comercial o contractual, elabora un formulario que permita identificar al cliente, conocer la actividad económica que desarrollen en caso de que el cliente no cuente con alguno de los datos mínimos de información solicitada, no se inicia la relación comercial y se mantiene un registro de los mismos.
A44: ¿¿¿¿ | C44: 8 | D44: Para los clientes y operaciones calificadas por la empresa como de bajo riesgo, aplica procedimientos de Debida Diligencia Simplificada, lo que en ningún caso implicará omitir la presentación de lo señalado en el artículo 12 normas de prevención de lavado de activos, financiamiento del terrorismo y la verificara de lo consignado.
A46: ¿¿¿¿¿¿¿¿¿¿¿¿ | C46: 9 | D46: Los sujetos obligados del sector que se dedique a las actividades de la construcción e intermediación e inversión inmobiliaria, deben registrar todas las operaciones y transacciones que realizan sus clientes. Sin embargo, en lo que respecta a la información del cliente, para aquellas transacciones u operaciones individuales o múltiples que en un mes sean realizadas en beneficio de una misma persona, cuyos montos sean menores a los diez mil dólares de los Estados Unidos de América (USD $ 10.000,00) o su equivalente en otras monedas, se requerirá información básica como número de identificación, nombres y apellidos completos, dirección y teléfono. En el mismo caso, y cuando el monto iguale o supere los diez mil dólares de los Estados Unidos de América (USD $ 10.000,00) o su equivalente en otras monedas, se solicitará como mínimo la información establecida en el artículo 10 de la presente resolución, y/o dependiendo del tipo de cliente, se aplicarán procedimientos de debida diligencia.
A48: ¿¿¿¿¿¿ | C48: 10 | D48: La información y documentación que debe conservar el sujeto obligado debe ser adecuada y suficiente para poder reconstruir los vínculos transaccionales y, eventualmente, puedan llegar a servir como elementos en análisis, investigaciones o procesos judiciales en materia de lavado de activos y financiamiento del terrorismo y otros delitos. Para estos propósitos, como mínimo, la información a ser archivada por la compañía es la siguiente:
A50: ¿¿¿ | D50: • | E50: Expediente del cliente que debe contener todos los documentos e información recopilada por el sujeto obligado durante la relación comercial, con los soportes de su verificación.
D51: • | E51: Perfil financiero y transaccional del cliente.
D52: • | E52: Archivos de operaciones y correspondencia comercial.
A53: ¿¿¿ | D53: • | E53: Información relacionada con el manejo de fondos cuya cuantía o características no guarden relación con la actividad económica del cliente, o cuyo origen no pueda justificarse, así como las transacciones complejas y/o inusuales.
A54: ¿¿¿ | D54: • | E54: Informes que sustenten las razones por las cuales una operación calificada por el sujeto obligado como inusual e injustificado no fue reportada a la Unidad de Análisis Financiero y Económico (UAFE).
A56: ¿¿¿ | C56: 11 | D56: La junta general de socios de la compañía debe designar un oficial de cumplimiento para coordinar las actividades de control, vigilancia, detección, prevención y reporte de operaciones o transacciones económicas inusuales e injustificadas.
A58: ¿¿¿ | D58: • | E58: El oficial de cumplimiento deberá ser independiente de las otras áreas de la compañía y estará dotado de facultades y recursos suficientes para cumplir adecuadamente sus funciones.
...

Sheet contrato lavado activo
C2: CONTRATO DE PROCEDIMIENTOS PREVIAMENTE CONVENIDOS ASUNTOS REQUERIDOS POR LEY ORGÁNICA DE PREVENCIÓN, DETECCIÓN Y ERRADICACIÓN DEL DELITO DE LAVADO DE ACTIVOS Y DEL FINANCIAMIENTO DE DELITOS
A4: ¿¿¿¿¿ | C4: La Compañía es sujeto obligado a reportar a la Unidad de Análisis Financiero y Económico (UAFE) Según el Art. 5. de la Ley Orgánica De Prevención, Detección y Erradicación del Delito de Lavado de Activos y del Financiamiento de Delitos, el cumplimiento de estas obligaciones deben ser verificados por un auditor externo por lo que se firma el presente contrato.
A6: ¿¿¿¿¿ | C6: Conste por el presente documento el Contrato de Procedimientos Previamente Convenidos sobre los Asuntos Requeridos por Ley Orgánica De Prevención, Detección y Erradicación del Delito de Lavado de Activos y del Financiamiento de Delitos que celebran “INMCAMPSA S.A.” y por otra parte 3 A.N.G. ADMINISTRACIÓN DE NEGOCIOS GERENCIALES CIA. LTDA., al tenor de las siguientes cláusulas:
C8: CLAUSULA PRIMERA: COMPARECIENTES.-
C10: Debido a lo antes mencionado concurren a celebrar el siguiente Contrato las siguientes Personas:
A12: ¿¿¿¿¿ | C12: a) Por una parte “INMCAMPSA S.A.” De Ruc # 0992395125001 de expediente # 118536 Representada Legalmente por la Sra. Pachar Celi Marcia Edith en calidad de GERENTE GENERAL – INMCAMPSA S.A., quien obra debidamente autorizado por la Junta general, parte a la que en adelante, para efectos del siguiente contrato, se podrá denominar LA COMPAÑÍA.
A14: ¿¿¿¿¿ | C14: b) Por otra parte, 3 A.N.G. ADMINISTRACIÓN DE NEGOCIOS GERENCIALES CIA. LTDA., con RUC# 0992541504001 debidamente calificado y registrado en la Superintendencia de Compañías con el SC-RNAE-No 662 y Representada Legalmente por Eco. Roy Cisneros Mejía en calidad de GERENTE GENERAL para efectos del presente contrato se le denominara “EL AUDITOR EXTERNO”.
A16: ¿¿¿¿ | C16: CLAUSULA SEGUNDA: OBJETO.- La compañía suscribe el contrato con el Auditor Externo y acepta, la revisión de los siguientes puntos, dispuestos por la Ley Orgánica De Prevención, Detección y Erradicación del Delito de Lavado de Activos y del Financiamiento de Delitos:
A18: ¿¿¿¿¿¿ | C18: 1. Revisaremos si la compañía cuenta con políticas y procedimientos de control para prevenir el lavado de activos, el financiamiento del terrorismo y otros delitos de conformidad con lo establecido en la presente norma; y, adoptar medidas de control apropiadas y suficientes, orientadas a evitar que puedan ser utilizados como instrumentos para realizar actividades vinculadas al lavado de activos y/o al financiamiento del terrorismo y otros delitos.
A20: ¿¿¿ | C20: 2. Se verificara las políticas que adopta la compañía para prevenir el lavado de activos, el financiamiento del terrorismo y otros delitos, cumple con los siguientes parámetros:
A22: ¿¿ | C22: · Las políticas y procedimientos incorporados le permitan administrar, evaluar y mitigar con eficacia los riesgos que se hayan identificado.
A25: ¿¿ | C25: · Abarca toda clase de productos o servicios que ofrece la compañía.
A27: ¿¿¿ | C27: · Asegura que los miembros de la compañía tengan el debido conocimiento, acatamiento y aplicación de las normativas legales y reglamentarias relacionadas con la prevención de lavado de activos y el financiamiento del terrorismo y otros delitos.
A29: ¿¿ | C29: · Minimiza el grado de exposición inherente al lavado de activos y al financiamiento del terrorismo y otros delitos.
A30: ¿¿ | C30: · Establece políticas de debida diligencia según el riesgo que la misma compañía ha identificado.
A31: ¿¿¿ | C31: · Garantiza la reserva y confidencialidad de la información reportada, conforme lo previsto en la Ley de Prevención, Detección y Erradicación del Delito de Lavado de Activos y del Financiamiento de Delitos.
A33: ¿¿¿ | C33: 3. Analizaremos los procedimientos de prevención para el lavado de activos, el financiamiento del terrorismo y otros delitos, que adoptado por la compañía le permiten:
... A36: ¿¿¿ | C36: · Detectar operaciones o transacciones económicas inusuales e injustificadas, para reportarlas oportunamente y con los sustentos del caso a la Unidad de Análisis Financiero y Económico (UAFE).
C37: · Atender los requerimientos de información formulados por autoridades competentes.
A39: ¿¿¿¿¿ | C39: 4. Verificaremos que los representantes legales o administradores, oficiales de cumplimiento, socios y empleados, estén obligados a guardar reserva y confidencialidad respecto de las operaciones que lleguen a su conocimiento en el ejercicio de sus funciones. Expresamente se les prohíbe informar de cualquier notificación que hubieren hecho a las autoridades competentes.
A40: ¿¿¿¿ | C40: 5. Verificaremos que el Manual de Prevención establezca las políticas y los procedimientos de control que adopte la compañía y disponga cómo deben operar los mecanismos de prevención estableciendo los procedimientos :
A41: ¿¿¿ | C41: · Implementa la vinculación de nuevos clientes, así como confirma y actualiza la información aportada por los clientes antiguos.
A42: ¿¿¿ | C42: · Conserva y protege los registros operativos y documentos relacionados con los clientes y aquellos documentos que sean solicitados por las autoridades.
A43: ¿¿¿ | C43: · Define los canales de comunicación e instancias de reporte entre el oficial de cumplimiento y demás áreas de la compañía.
C44: · Atiende oportunamente los reportes periódicos de acuerdo a la ley.
A45: ¿¿¿ | C45: · Detecta señales de alerta de acuerdo a la naturaleza de los productos y servicios que ofrece la compañía.
C46: · Cumple las políticas de debidas diligencias que adopte al sujeto obligado.
A49: ¿¿ | C49: 6. Verificaremos si el manual ha sido conocido por todo el personal y pueda ser actualizado, en caso de requerirlo la compañía.
A51: ¿¿¿¿¿ | C51: 7. Revisaremos que la compañía al inicio de la relación comercial o contractual, elabora un formulario que permita identificar al cliente, conocer la actividad económica que desarrollen en caso de que el cliente no cuente con alguno de los datos mínimos de información solicitada, no se inicia la relación comercial y se mantiene un registro de los mismos.
A52: ¿¿¿¿¿ | C52: 8. Se revisara si los clientes y operaciones calificadas por la empresa como de bajo riesgo, apliquen procedimientos de Debida Diligencia Simplificada, lo que en ningún caso implicará omitir la presentación de lo señalado en el artículo 12 normas de prevención de lavado de activos, financiamiento del terrorismo y la verificara de lo consignado.
A54: ¿¿¿¿¿¿¿¿¿¿¿ | C54: 9. Se verificara que el sujeto obligado del sector que se dedique a las actividades de la construcción e intermediación e inversión inmobiliaria, registren todas las operaciones y transacciones que realizan sus clientes. Sin embargo, en lo que respecta a la información del cliente, para aquellas transacciones u operaciones individuales o múltiples que en un mes sean realizadas en beneficio de una misma persona, cuyos montos sean menores a los diez mil dólares de los Estados Unidos de América (USD $ 10.000,00) o su equivalente en otras monedas, se requerirá información básica como número de identificación, nombres y apellidos completos, dirección y teléfono. En el mismo caso, y cuando el monto iguale o supere los diez mil dólares de los Estados Unidos de América (USD $ 10.000,00) o su equivalente en otras monedas, se solicitará como mínimo la información establecida en el artículo 10 de la presente resolución, y/o dependiendo del tipo de cliente, se aplicarán procedimientos de debida diligencia.
A56: ¿¿¿¿¿¿ | C56: 10. Se revisara la información y documentación que deba conservar el sujeto obligado sea adecuada y suficiente para poder reconstruir los vínculos transaccionales y, eventualmente, puedan llegar a servir como elementos en análisis, investigaciones o procesos judiciales en materia de lavado de activos y financiamiento del terrorismo y otros delitos. Para estos propósitos, como mínimo, la información a ser archivada por la compañía es la siguiente:
A57: ¿¿¿ | C57: · Expediente del cliente que debe contener todos los documentos e información recopilada por el sujeto obligado durante la relación comercial, con los soportes de su verificación.
C58: · Perfil financiero y transaccional del cliente.
C59: · Archivos de operaciones y correspondencia comercial.
A60: ¿¿¿¿ | C60: · Información relacionada con el manejo de fondos cuya cuantía o características no guarden relación con la actividad económica del cliente, o cuyo origen no pueda justificarse, así como las transacciones complejas y/o inusuales.
A61: ¿¿¿ | C61: · Informes que sustenten las razones por las cuales una operación calificada por el sujeto obligado como inusual e injustificado no fue reportada a la Unidad de Análisis Financiero y Económico (UAFE).
A62: ¿¿¿¿ | C62: 11. Se verificara si la junta general de socios de la compañía ha designado un oficial de cumplimiento para coordinar las actividades de control, vigilancia, detección, prevención y reporte de operaciones o transacciones económicas inusuales e injustificadas.
A63: ¿¿¿ | C63: · El oficial de cumplimiento deberá ser independiente de las otras áreas de la compañía y estará dotado de facultades y recursos suficientes para cumplir adecuadamente sus funciones.
A66: ¿¿¿ | C66: · El sujeto obligado notificará a la Superintendencia de Compañías y Valores la designación del oficial de cumplimiento de la compañía, dentro de los cinco (5) días siguientes a que se haya efectuado.
...

Sheet Carta entrega inf. L-A
H3: Santo Domingo, 18 de abril del 2022 | I3: =+'OPINION pymes con anexo '!I72 -> Agosto, 18 del 2023
B6: =+'6 INFORME BALANCES'!L24 -> Sr. Eduardo Mendoza Hurtado
B7: Gerente General
B8: =+'OPINION pymes con anexo '!C75 -> TABACALERA MENHURSA S.A.
A11: ¿¿¿¿ | B11: Por medio de la presente estamos haciendo entrega del Informe de Auditoría Externa en prevención, detección y erradicación del delito de lavado de activos y del financiamiento del Terrorismo, y el Respectivo Contrato, para que sean firmados
A14: ¿ | B14: Procederemos a retirar nuestra copia cuando ustedes nos indiquen .
B16: Reiteramos nuestro agradecimiento por la confianza depositada
B23: ………………………………..
B24: Econ. Roy Cisneros Mejía
B25: Gerente General
B31: F…………………………….
B32: Recibido

Sheet 30CAPI VI 
C5: INFORME DE AUDITORÍA Y ANEXOS
C9: =+'25CAPI IV'!C8 -> TABACALERA MENHURSA S.A.
C16: V I
C21: INFORME SOBRE LA LEY DE PREVENCIÓN, DETECCIÓN Y ERRADICACIÓN DEL DELITO DE LAVADO DE ACTIVOS Y DEL FINANCIAMIENTO DE DELITO.

Sheet PAPELES
A1: sumaria | C1: VERIFICACIONES DE PAPELES DE CSED
C2: ROSA VALAREZO
A3: 101
B4: 1. Pasar al sobregiro contable pasivos el valor del banco Banco Pichincha Unidad de Negocios 3347028104
A5: 102
B6: 2. Falta confirmaciones de cuentas por cobrar
B7: 3. Falta confirmación de cuenta por cobrar relacionada
B8: 4. Falta poner referencia a los papeles de trabajo
B9: 5. Falta trabajo sobre los empleados
A10: 111
B11: 6. Verificar los incrementos y las dimensiones soportar y pedir listado de activos fijos con fechas de vencimiento
B12: 7. Soportar los 304mil
B13: 8. Falta poner referencia a los papeles de trabajo
A15: 202
B16: 9. Dejar la evidencia de los seleccionados para circula como ls cartas borradores de la circulación
B17: 10. Falta de trabajo de impuestos ligar
B18: 11. Falta poner referencia a los papeles de trabajo
A20: 204
B21: 12. Falta el movimiento en la provisión a trabajadores 2.12.01.01.01.001 de incremento y la obligación
B22: 13. Falta de trabajo 2.11.01.01.01.002
B23: 14. Falta papeles de trabajo
A24: 205
B25: 15. Falta de trabajo no está soportado el incremento y la obligación
B26: 16. Falta poner referencia a los papeles de trabajo
A27: 217
B28: 17. Falta de trabajo no está soportado la disminución o pago este es un acuerdo con el sri
B29: 18. Falta poner referencia a los papeles de trabajo
A30: 303
B31: 19. | C31: Falta de trabajo no está realizado el movimiento del patrimonio con las movimientos reales que tubo e patrimonio soportar la cuenta utilidades del ejercicio Falta poner
B32: 20. referencia a los papeles de trabajo
A34: 601
B35: 21 | C35: pedir el contrato y la factura del ingreso para liquidar estos valores
A38: 707
B39: 23 | C39: Falta de trabajo no está soportado falta las sumarias
B40: 24 | C40: Falta poner referencia a los papeles de trabajo
B41: 25 | C41: probrar la cuentas
B42: 26 | C42: ligar las depreciaciones
B43: 27 | C43: ligar los decimos y gastos con trabajadores
B44: 28 | C44: ligar los sueldo a la cuentas donde se probo los sueldos sacados de las planillas
B45: 29 | C45: ligar Capacidad Contratada Csed.net
...

Sheet INFORME GERENTE 
F2: INFORME DE GERENTE
H4: Buena Fe, 18 de agosto de 2023
B6: A los señores Socios y Directiva de
B7: =+'6 INFORME BALANCES'!C9 -> TABACALERA MENHURSA S.A.
A9: ¿¿¿¿¿ | B9: En mi calidad de Gerente General y en cumplimiento a la función que se me asigna el numeral 4 del Art. 321 de la Ley de Compañías, cúmpleme informarles que he examinado el balance de la Compañía al 31 de Diciembre del 2022 y el correspondiente estado de resultados, los flujos de efectivo, el estado de evolución del patrimonio, que le es relativo por el año terminado en esa fecha.
B11: 1. Respecto a la ventas
A12: ¿¿¿¿ | B12: Un análisis de las tendencias de ventas es una revisión de las mediciones relacionadas con las ventas o indicadores claves de rendimiento durante un período de tiempo específico. El período puede ser a corto, mediano o largo plazo. Las tendencias en las ventas pueden subir, bajar o permanecer sin cambios como es el caso del los periodos analizados.
G14: =+'6 INFORME BALANCES'!H38 -> 45291 | H14: =+'6 INFORME BALANCES'!I38 -> 44926
C15: Ventas Gravadas con 0% | D15: Venta Netas | G15: =+'5 PG101'!L11 -> 0 | H15: =+'5 PG101'!D11 -> 1040371.6
B17: 2. Respecto al comparativo de la ganancia bruta antes de gastos
B18: Los indicadores sobre los ingreso netos nos dieron el siguiente resultado:
G20: =+G14 -> 45291 | H20: =+H14 -> 44926
D21: Ganancia bruta antes de gastos | G21: =+'6 INFORME BALANCES'!H115 -> 0 | H21: =+'6 INFORME BALANCES'!I115 -> 73889.818
B23: 3. Respecto al efectivo y sus equivalentes
B24: La empresa al cierre del ejercicio mostro los siguientes resultados:
G26: =+G14 -> 45291 | H26: =+H14 -> 44926
D27: Equivalente de efectivo | G27: =+'101'!M12 -> 0 | H27: =+'101'!D12 -> 21075.33
B29: 4. Respecto a la cartera por pagar
A30: ¿¿ | B30: Toda la cartera del periodo anterior fue recuperada y la cartera de este periodo se estima que los clientes que adeudan cancelara a mas tardar los primeros tres meses
G32: =+G26 -> 45291 | H32: =+H26 -> 44926
C33: Cuentas por pagar (Corrientes) | G33: =+'6 INFORME BALANCES'!H66 -> 0 | H33: =+'6 INFORME BALANCES'!I66 -> 502.05
C34: Cuentas por pagar (No Corrientes) | G34: =+'6 INFORME BALANCES'!H76 -> 0 | H34: =+'6 INFORME BALANCES'!I76 -> 815103.45
G35: =SUM(G33:G34) -> 0 | H35: =SUM(H33:H34) -> 815605.5
B39: 5. Respecto a la utilidad para trabajadores y accionistas
A40: ¿¿ | B40: La utilidad de este periodo, utilidad a trabajadores y el impuesto a la renta es como sigue aplicando la normativa tributaria permitida.
G41: =+G32 -> 45291 | H41: =+H32 -> 44926
C42: PARTICIPACIÓN A TRABAJADORES | G42: =+'5 PG101'!L44 -> 0 | H42: =+'5 PG101'!D44 -> 0
C43: IMPUESTO A LA RENTA | G43: =+'5 PG101'!L45 -> 0 | H43: =+'5 PG101'!D45 -> 0
C44: RESULTADOS DEL EJERCICIO | G44: =+'5 PG101'!L48 -> 0 | H44: =+'5 PG101'!D48 -> -24472.242
B46: 6. Información importante a revelar
A48: ¿¿¿ | B48: 6.1. Sobre el Cumplimiento de objetivos previstos para el ejercicio económico materia del informe. Las operaciones realizadas en el período reflejan el cumplimiento de los objetivos planteados por mi administración.
A50: ¿¿¿ | B50: Debo informar a la junta que se han cumplido con las disposiciones de la Junta General y el Directorio de la compañía durante el periodo de gestión. Las operaciones realizadas en el año 2022 reflejan el cumplimiento de objetivos interpuestos a la administración.
A52: ¿¿¿¿ | B52: 6.2. Sobre los hechos extraordinarios producidos durante el ejercicio, en el ámbito administrativo, laboral y legal: Con fecha 2020-09-18, recibí el nombramiento por dos años como gerente general y se nombró con misma fecha como presidente a MENDOZA PALMA ERWIN EDUARDO por dos años.
A54: ¿¿¿¿¿ | B54: 6.3. Sobre la Situación financiera de la compañía al cierre del ejercicio y de los resultados anuales, comparados con los del ejercicio precedente: Se presentan en los cuadros que anteceden a este informe y los correspondientes balances. Se utilizó en la conciliación tributaria la amortización de las pérdidas acumuladas de períodos anteriores que permitió bajar impuestos en el período.
A56: ¿¿¿¿ | B56: Recomendaciones a la junta general respecto de políticas y estrategias para el siguiente ejercicio económico: Con base a los resultados obtenidos y la leve recuperación del período se solicita a la junta apoyar la estrategia financiera que permita el crecimiento de la compañía.
A58: ¿¿¿ | B58: 6.4. Sobre el estado de cumplimiento de las normas sobre propiedad intelectual y derechos de autor por parte de la compañía: La compañía cumple con las normas de propiedad intelectual y derechos de autor.
B60: El gerente a la directiva
A61: ¿¿¿ | B61: Por lo expuesto someto a consideración la aprobación final del balance general de a, al 31 de Diciembre del 2022 y el correspondiente estado de resultados por el año terminado en esa fecha.
C65: …..........................................................
C66: =+'6 INFORME BALANCES'!L24 -> Sr. Eduardo Mendoza Hurtado
...

Sheet INF COMISARIO
B9: INFORME DE COMISARIO 2022
B11: =+'INFORME GERENTE '!B7 -> TABACALERA MENHURSA S.A.
B17: DIRIGIDO A: | E17: ACCIONISTAS Y JUNTA DIRECTIVA
B18: FECHA: | E18: Agosto 18 de 2023
B22: Elaborado por:
B27: ___________________________
B28: Ing. Maricela Geoconda Pilligua
B29: Comisario Principal
D45: Señores accionistas y Junta Directiva de
A46: ¿ | D46: =+B11 -> TABACALERA MENHURSA S.A.
D47: Buena Fe, Ecuador
A49: ¿¿ | B49: Pongo a su consideración el informe de Comisario por el año 2022, de acuerdo a los lineamientos y disposiciones legales:
B51: 1. ANTECEDENTES LEGALES
A52: ¿¿¿¿ | B52: * | C52: El Art. 274 establece que las compañías, de creer conveniente, podrán nombrar comisarios. Cuando por disposición estatutaria se hubiere acordado la existencia de comisarios, éstos se sujetarán a las disposiciones establecidas en esta Ley con relación a sus atribuciones, derechos y obligaciones. Caso contrario, las disposiciones de esta Ley relacionadas con los comisarios no tendrán aplicación.
A54: ¿¿¿ | B54: * | C54: Los comisarios, socios o no, designados si el estatuto social hubiere acordado su existencia, tienen derecho ilimitado de inspección y vigilancia sobre todas las operaciones sociales, sin dependencia de la administración y en interés de la compañía.
A56: ¿¿ | B56: * | C56: La resolución No. 92.1.4.3.0014 de la Superintendencia de Compañías establece el cumplimiento de los requisitos mínimos que deben contener los informes de Comisarios.
A58: ¿ | B58: * | C58: La Junta General de Accionistas designó como comisario principal a Maricela Geoconda Pilligua.
B60: 2. RESPONSABILIDAD DEL COMISARIO
A61: ¿¿¿¿ | C61: Mi responsabilidad es expresar una opinión sobre los estados financieros de la Compañía, basada en la revisión efectuada y, sobre el cumplimiento por parte de la Administración de las normas legales, estatutarias Y reglamentarias, así como de las resoluciones de la Junta General, y de las recomendaciones y autorizaciones de la Administración.
A63: ¿¿¿¿ | C63: Esta revisión fue efectuada siguiendo los lineamientos de las normas internacionales de auditoría, pruebas selectivas de los registros contables y evidencia que soporta los importes y revelaciones incluidos en los estados financiero, evaluación de control interno y otros procedimientos de revisión.
A65: ¿¿¿¿¿¿ | C65: He obtenido de los administradores, información de las operaciones, registros contables y documentación sustentadora de las transacciones Adicionalmente, he revisado el estado de situación financiera al 31 de diciembre del 2022 y el correspondiente estado de resultados por el año terminado en esa fecha, así como los libros sociales, las actas de Junta de Accionistas. Considero que los resultados de la revisión proveen bases apropiadas para expresar mi opinión.
B67: 3. CUMPLIMIENTO DE RESOLUCIONES
A68: ¿¿¿¿ | C68: El resultado de la revisión efectuada, a las transacciones registradas, los actos de los administradores, normas legales, estatutarias y reglamentarias, así como las resoluciones adoptadas por las Juntas de Accionistas, los libros de actas de Juntas de accionistas, libro de acciones y accionistas, se conservan de conformidad con disposiciones legales.
B70: 4. EVALUACIÓN DEL CONTROL INTERNO
A72: ¿¿¿¿ | C72: La evaluación del entorno, normas, procedimientos y políticas nos han permitido dirimir la razonabilidad de la operatividad de TABACALERA MENHURSA S.A., en tal virtud permite certificar que los procedimientos y controles implementados por la gerencia, protegen y salvaguardan la integridad económica de los activos, obligaciones y resultados de la compañía.
B74: 5. DISPOSICIONES CONSTANTES DE LA LEY.
A76: ¿¿¿¿ | C76: En Cumpliendo con lo que establece el Art 321 de la ley de compañías, la compañía TABACALERA MENHURSA S.A. informó en los plazos establecidos a la Superintendencia de Compañías, Valores y Seguros de la contratación de 3ANG ADMINISTRACION DE NEGOCIOS GERENCIALES CIA. LTDA. como auditores externos por el período 2022.
B78: 6. SOBRE LA SITUACIÓN FINANCIERA.
A80: ¿¿¿¿ | C80: En mi opinión, los estados financieros presentan razonablemente en todos los aspectos importantes, la situación financiera de TABACALERA MENHURSA S.A., al 31 de diciembre de 2022, de conformidad con las disposiciones de la Ley de Compañías y principios contables vigentes en el Ecuador.
C82: La composición del balance general del 2022 y 2021 es el siguiente:
G84: 44926 | H84: 44561
C86: Activos
C87: Activos corrientes:
C88: Efectivo | G88: =+'6 INFORME BALANCES'!H42 -> 0 | H88: =+'6 INFORME BALANCES'!I42 -> 21075.33
C89: Otros activos corrientes | G89: =+'6 INFORME BALANCES'!H44 -> 0 | H89: =+'6 INFORME BALANCES'!I44 -> 0
C90: Inventarios | G90: =+'6 INFORME BALANCES'!H45 -> 0 | H90: =+'6 INFORME BALANCES'!I45 -> 0
C92: Total activos corrientes | G92: =SUM(G88:G91) -> 0 | H92: =SUM(H88:H91) -> 21075.33
C94: Activos no corrientes:
C95: Propiedad, planta y equipo | G95: =+'6 INFORME BALANCES'!H51 -> 0 | H95: =+'6 INFORME BALANCES'!I51 -> 770873.64
C97: Total activos no corrientes | G97: =SUM(G95:G96) -> 0 | H97: =SUM(H95:H96) -> 770873.64
...

Sheet ACTA DE JNTA 2022
A1: ¿¿ | B1: ACTA DE LA JUNTA GENERAL EXTRAORDINARIA DE ACCIONISTAS DE LA COMPAÑIA TABACALERA MENHURSA S.A.
A3: ¿¿¿¿ | B3: En la provincia de Los Rios, a los dieciocho días del mes de agosto del dos mil veintitres, a las diez horas, en las oficinas de la compañía ubicadas en las calles Avenida 7 de agosto en la ciudad San Jacinto de Buena Fe, ciudadela Recinto Federico Intriago, comparece los siguientes accionistas de la compañía:
A5: ¿¿¿¿¿¿ | B5: Por un lado, MENDOZA HURTADO ANDREA KATHERINE, propietario de doscientas (200) acciones, por otro lado, MENDOZA HURTADO EDUARDO ISRAEL, propietario de doscientas (200) acciones, y MENDOZA PALMA ERWIN EDUARDO propietario de cuatrocientas (400) acciones. Todas las acciones son ordinarias y nominativas. pagadas en su totalidad. de un dólar de los Estados Unidos de América cada una, que en proporción a su valor pagado. dan derecho a igual número de votos.
A7: ¿¿¿¿ | B7: Preside la Junta, El señor MENDOZA PALMA ERWIN EDUARDO en calidad de Presidente, y en calidad de Secretario el Señor MENDOZA HURTADO EDUARDO ISRAEL y amparado en el Art. 238 de la Codificación a la Ley de Compañías acuerdan construirse en Junta General Extraordinaria de Accionistas, para conocer y resolver los siguientes puntos del orden del día:
B9: 1. Conocer y aprobar los estados financieros de la compañía, periodo 2022
B10: 2. Conocer y aprobar el Informe de Gerente, periodo 2022
B11: 3. Conocer y aprobar el Informe de Comisario, periodo 2022
B12: 4. Conocer y aprobar el Informe de Auditoria, periodo 2022
B13: 5. Conocer y resolver sobre el destino de los resultados del período 2022.
A15: ¿¿ | B15: Por secretaría se confirma la presencia del 100% del Capital Suscrito y Pagado y procede a dar lectura del primer punto: 1. Conocer y aprobar los estados financieros de la compañía, periodo 2022.
A17: ¿¿¿¿ | B17: Toma la palabra el presidente de la junta, quien manifiesta que el Estado de Situación Financiera, Estado de Resultados integrales, el Estado de Cambio en el Patrimonio, y el Estado de Flujo de Efectivo correspondientes al ejercicio económico del año 2022 se encuentra acorde a las Normas Internacional de Información Financieras NIIF, los accionistas han revisado los balances y aprueban por unanimidad.
A19: ¿¿¿¿ | B19: Se procede con el segundo punto del orden del día: 2. Conocer y aprobar el Informe de Gerente, periodo 2022, El Gerente Señor MENDOZA HURTADO EDUARDO ISRAEL, salva su voto debido a que es su gestion la que se pone en consideracion, toma la palabra el Señor MENDOZA PALMA ERWIN EDUARDO en calidad de Presidente y se procede aprobar la gestion del gerente.
A21: ¿¿¿ | B21: Se procede con el tercer punto del orden del día: 3. Conocer y aprobar el Informe de Comisario, periodo 2022. Para esto se da lectura al informe, la junta previamente recibió los informes y no tienen observaciones al mismo, y lo dan por aprobado.
A23: ¿¿¿¿ | B23: Se procede con el cuarto punto del orden del día: 4. Conocer y aprobar el Informe de Auditoria, periodo 2022 por parte de la compañía auditora 3ANG Administracion de Negocios Gerenciales Cia. Ltda.. Se procede a dar lectura del Informe de Auditoria, la junta previamente recibió los informes y no tienen observaciones al mismo lo dan por aprobado.
A25: ¿¿¿ | B25: Se procede con el quinto punto del orden del día: 5. Conocer y resolver sobre el destino de las perdidas del período 2022. La junta resuelve por unanimidad de todos los votos válidos, acumular las perdidas del presente año.
A27: ¿¿¿ | B27: Concluida la Junta General Extraordinaria de Accionistas y no habiendo puntos más que tratar, de conformidad con el Art. 238 de la Ley de Compañías, se concede un receso de 15 minutos para la redacción del acta. Para constancia firman:
B34: …............................................ | F34: ................................................
B35: Mendoza Palma Erwin E. | F35: Mendoza Hurtado Eduardo I.
B36: Presidente / Accionista | F36: Secretario / Accionista
D43: …............................................
D44: Mendoza Hurtado Andrea K.
D45: Accionista

Sheet 29 INDEPENDENCIA EQ
C5: CERTIFICACIÓN JURAMENTADA
C9: INDEPENDENCIA DEL EQUIPO DE AUDITORÍA
C11: AUDITORIA A LOS ESTADOS FINANCIEROS POR EL PERIODO 2023 DE LA COMPAÑÍA.
C13: TABACALERA MENHURSA S.A.
C17: 3 A.N.G ADMINISTRACION DE NEGOCIOS GERENCIALES CIA. LTDA., CERTIFICA BAJO JURAMENTO que el equipo de auditoría participante y el suscriptor del informe, no se encuentran incursos en ninguna de las prohibiciones establecidas en el artículo 197 de la Ley de Mercado de Valores y los artículos 328, 329 de la ley de compañías .
C22: 3ANG Administración de Negocios Gerenciales. Cía. Ltda.
C23: Registro Nacional de Auditores Externos
C24: SC – RNAE-662
C25: Econ. Roy Cisneros Mejía
C26: SOCIO

Sheet 28 Certif del equipo (2)
C10: CERTIFICADO
A18: ¿¿¿¿ | C18: Por medio de la presente hago constar que la compañía 3 A.N.G ADMINISTRACION DE NEGOCIOS GERENCIALES CIA. LTDA. Con Ruc 0992541504001, fue nuestro auditor externo en el año 2023. En la que participaron las siguientes Personas:
C21: Econ Roy Cisneros Mejía.
C22: Ing. Maria Elizabeth Palacios
C25: Cumpliendo satisfactoriamente con sus compromisos.
C28: Constancia que expido a solicitud de la parte interesada. Por requerimientos de la Superintendencia de Compañias, Valores y Seguros.
C29: =+'OPINION pymes con anexo '!I72 -> Agosto, 18 del 2023
C35: _________________________________________
C36: =+'6 INFORME BALANCES'!L24 -> Sr. Eduardo Mendoza Hurtado
C37: =+'6 INFORME BALANCES'!L25 -> Gerente General

Sheet 27CAPI V
C5: INFORME DE AUDITORÍA Y ANEXOS
C9: TABACALERA MENHURSA S.A.
C15: V
C21: CERTIFICACIONES JURAMENTADAS

Sheet 26CARTA DE REPRESENN
C2: TABACALERA MENHURSA S.A.
C4: R.U.C.No. 1291784468001
C6: Señores :
C7: 3 A.N.G. ADMINISTRACION DE NEGOCIOS GERENCIALES CIA. LTDA.
A9: ¿¿¿¿¿¿¿¿¿¿¿ | C9: Esta carta de representación se provee en relación con sus auditorías de los estados financieros de la compañía TABACALERA MENHURSA S.A., los cuales comprenden los balances generales al 31 de diciembre de 2023 y los correspondientes estados de resultados, cambios en el patrimonio, flujos de efectivo y las notas a los estados financieros por los años terminados en esas fechas, cuyo examen se efectuó con el propósito de expresar una opinión sobre si dichos estados financieros presentan razonablemente, en todos los aspectos de importancia material, la situación financiera de la compañía TABACALERA MENHURSA S.A., los resultados de sus operaciones y sus flujos de efectivo de acuerdo con normas internacionales de contabilidad y las normas de información financiera generalmente aceptados en Ecuador y si dichos principios fueron aplicados de manera uniforme.
A11: ¿¿¿¿¿¿¿¿¿¿¿ | C11: Reconocemos que estos estados financieros, preparados y presentados de acuerdo con principios de contabilidad generalmente aceptados en Ecuador, son de nuestra responsabilidad y previamente a su emisión nos hemos cerciorado del cumplimiento satisfactorio de las afirmaciones explícitas e implícitas contenidas en los mismos(integridad, existencia, exactitud, derechos y obligaciones, valuación y presentación y revelación de los hechos económicos), por lo que aprobamos estos estados financieros. Igualmente, reconocemos que esta responsabilidad incluye: diseñar, implementar y mantener el control interno relevante para preparación y presentación de estados financieros libres de errores de importancia material, bien sea por fraude o error; seleccionar y aplicar políticas contables apropiadas, así como establecer estimados contables que sean razonables en las circunstancias.
A13: ¿¿¿¿¿¿¿ | C13: Declaro que la información financiera bajo las Normas Internacionales de Información Financiera NIIF presentada a ustedes como auditores externos., revela todas las transacciones económicas realizadas por la compañía que yo represento en el periodo 2023 y me declaro responsable como representante legal de la compañía respecto a la veracidad de la información incorporada en los estados financieros referidos al ejercicio terminado al 31 de diciembre de 2023, de acuerdo al siguiente detalle.
D15: - | E15: Estado de Situación Financiera
D16: - | E16: Estado de Resultado Integral
D17: - | E17: Estado de Cambios en el Patrimonio
D18: - | E18: Estado de Flujo de Efectivo
D19: - | E19: Políticas Contables
D20: - | E20: Notas Explicativas a los Estados Financieros
A22: ¿¿ | C22: Así también informar a ustedes que los mayores contables que respaldan los estados financieros antes mencionados son confiables, verificables y reposan en nuestros archivos.
A24: ¿¿¿¿ | C24: Hemos efectuado las debidas indagaciones con los directores y funcionarios de la compañía que tienen los conocimientos y la experiencia relevantes. Por lo tanto, confirmamos, a nuestro leal saber y entender, las siguientes representaciones efectuadas a ustedes durante el desarrollo de su trabajo:
A26: ¿¿¿¿ | C26: 1. Hemos cumplido nuestras responsabilidades, de conformidad con los términos del contrato de prestación de servicios , en relación con la preparación y presentación de los estados financieros, de acuerdo con principios de contabilidad generalmente aceptados en Ecuador y la Superintendencia de Compañías
A28: ¿¿ | C28: 2. Los métodos de medición y los supuestos significativos que se utilizaron para establecer estimaciones contables, son apropiados.
A30: ¿¿¿ | C30: 3. No hay eventos posteriores a los estados financieros que requieran ajustes o revelación en notas, de conformidad con los principios de contabilidad generalmente aceptados en Ecuador.
A32: pp | C32: 4. Los efectos de los errores no corregidos son inmateriales, individualmente y agregados, a los estados financieros en su conjunto.
A34: pp | C34: 5. Le hemos dado acceso a toda la información relevante para la preparación de los estados financieros, tales como los registros contables y documentación de respaldo.
A36: pp | C36: 6. Hemos proporcionados todas las actas de las reuniones de Accionistas y de la Junta Directiva, se ha entregado a ustedes para su verificación.
A38: ¿¿¿ | C38: 7. Hemos proporcionado toda la información adicional que ustedes nos han solicitado para el propósito de su auditoría, y acceso sin restricciones a las personas de la Compañía de las cuales ustedes determinaron necesario obtener evidencia de auditoría.
A40: ¿¿¿ | C40: 8. Hemos proporcionado toda la información relacionada a controversias judiciales que afecten a la empresa para el propósito de su auditoría con el acceso sin restricciones a las cuales ustedes determinaron necesario obtener evidencia de auditoría.
C47: ________________________________________ | H47: ________________________________________
C48: =+'6 INFORME BALANCES'!L24 -> Sr. Eduardo Mendoza Hurtado | H48: =+'6 INFORME BALANCES'!L28 -> Sr. Alfonso Solorzano Moncada
C49: =+'6 INFORME BALANCES'!L25 -> Gerente General | H49: =+'6 INFORME BALANCES'!L29 -> Contador

Sheet 25CAPI IV
C4: INFORME DE AUDITORÍA Y ANEXOS
C8: TABACALERA MENHURSA S.A.
C14: IV
C20: CARTA DE REPRESENTACIÓN

Sheet 24CAPI III
C3: INFORME DE AUDITORÍA Y ANEXOS
C7: =+'23CAPI II'!C9 -> TABACALERA MENHURSA S.A.
C13: III
C19: COMUNICACIÓN DE DEFICIENCIAS DE CONTROL INTERNO

Sheet 23CAPI II
C4: INFORME DE AUDITORÍA Y ANEXOS
C9: =+'22CAPI I'!C10 -> TABACALERA MENHURSA S.A.
C14: I I
C19: INFORME DE LOS AUDITORES INDEPENDIENTES

Sheet 22CAPI  I
C5: INFORME DE AUDITORÍA Y ANEXOS
C10: =+'8 CONCILIA DEL PATRIMONIO'!B2 -> TABACALERA MENHURSA S.A.
C17: I
C23: ACTA DE ENTREGA
C29: =+'6 INFORME BALANCES'!L24 -> Sr. Eduardo Mendoza Hurtado
C30: GERENTE GENERAL
A34: ¿¿¿ | C34: Por medio del presente y una vez aprobado el borrador, estamos haciendo entrega de dos ejemplares del Informe de Auditoría Externa, y la Comunicación de Deficiencias de Control Interno, correspondiente al período auditado 2023, para que sean firmados por ustedes.
A37: ¿¿ | C37: Por favor, nuestro ejemplar procederemos a retirar cuando ustedes nos indiquen.
A40: ¿¿ | C40: Reiteramos nuestro agradecimiento por la confianza depositada.
C44: ---------------------------------------------
C45: Econ. Roy Cisneros Mejia
C46: Gerente
C50: ---------------------------------------------
C51: Recibido por
C52: =+'6 INFORME BALANCES'!L28 -> Sr. Alfonso Solorzano Moncada
A54: ¿¿¿ | C54: Con fecha ______/______/_______estamos entregando a ustedes sus originales firmados para que sigan con los procedimientos ante la Superintendencia de Compañias, Valores y Seguros.

Sheet 2 BL preli

Sheet 101 anterior
S1: Valor no deducible
A2: FORMULARIO RENTA SOCIEDADES
A4: OPERACIONES CON PARTES RELACIONADAS LOCALES Y/O DEL EXTERIOR
B5: CON PARTES RELACIONADAS LOCALES
C6: Operaciones de activo | N6: 3 | O6: 1 BL anterior=SUMAR.SI('1 BL anterior'!A:A;N6;'1 BL anterior'!E:E)
C7: Operaciones de pasivo | N7: 4 | O7: =SUMIF('1 BL anterior'!A:A,N7,'1 BL anterior'!E:E) -> 0 | AC7: =+O7-AA7-AB7 -> 0
C8: Operaciones de ingreso | N8: 5 | O8: =SUMIF('1 BL anterior'!A:A,N8,'1 BL anterior'!E:E) -> 0 | AC8: =+O8-AA8-AB8 -> 0
C9: Operaciones de egreso | N9: 6 | O9: =SUMIF('1 BL anterior'!A:A,N9,'1 BL anterior'!E:E) -> 0 | AC9: =+O9-AA9-AB9 -> 0
C10: Operaciones de regalías, servicios técnicos, administrativos, de consultoría y similares | N10: 7 | O10: =SUMIF('1 BL anterior'!A:A,N10,'1 BL anterior'!E:E) -> 0 | AC10: =+O10-AA10-AB10 -> 0
B11: CON PARTES RELACIONADAS EN PARAÍSOS FISCALES, JURISDICCIONES DE MENOR IMPOSICIÓN Y RÉGIMENES FISCALES PREFERENTES | AC11: =+O11-AA11-AB11 -> 0
C12: Operaciones de activo | N12: 8 | O12: =SUMIF('1 BL anterior'!A:A,N12,'1 BL anterior'!E:E) -> 0 | AC12: =+O12-AA12-AB12 -> 0
C13: Operaciones de pasivo | N13: 9 | O13: =SUMIF('1 BL anterior'!A:A,N13,'1 BL anterior'!E:E) -> 0 | AC13: =+O13-AA13-AB13 -> 0
C14: Operaciones de ingreso | N14: 10 | O14: =SUMIF('1 BL anterior'!A:A,N14,'1 BL anterior'!E:E) -> 0 | AC14: =+O14-AA14-AB14 -> 0
C15: Operaciones de egreso | N15: 11 | O15: =SUMIF('1 BL anterior'!A:A,N15,'1 BL anterior'!E:E) -> 0 | AC15: =+O15-AA15-AB15 -> 0
C16: Operaciones de regalías, servicios técnicos, administrativos, de consultoría y similares | N16: 12 | O16: =SUMIF('1 BL anterior'!A:A,N16,'1 BL anterior'!E:E) -> 0 | AC16: =+O16-AA16-AB16 -> 0
B17: CON PARTES RELACIONADAS EN OTRAS JURISDICCIONES O RÉGIMENES DEL EXTERIOR | AC17: =+O17-AA17-AB17 -> 0
C18: Operaciones de activo | N18: 13 | O18: =SUMIF('1 BL anterior'!A:A,N18,'1 BL anterior'!E:E) -> 0 | AC18: =+O18-AA18-AB18 -> 0
C19: Operaciones de pasivo | N19: 14 | O19: =SUMIF('1 BL anterior'!A:A,N19,'1 BL anterior'!E:E) -> 0 | AC19: =+O19-AA19-AB19 -> 0
C20: Operaciones de ingreso | N20: 15 | O20: =SUMIF('1 BL anterior'!A:A,N20,'1 BL anterior'!E:E) -> 0 | AC20: =+O20-AA20-AB20 -> 0
C21: Operaciones de egreso | N21: 16 | O21: =SUMIF('1 BL anterior'!A:A,N21,'1 BL anterior'!E:E) -> 0 | AC21: =+O21-AA21-AB21 -> 0
C22: Operaciones de regalías, servicios técnicos, administrativos, de consultoría y similares | N22: 17 | O22: =SUMIF('1 BL anterior'!A:A,N22,'1 BL anterior'!E:E) -> 0 | AC22: =+O22-AA22-AB22 -> 0
B23: TOTAL OPERACIONES CON PARTES RELACIONADAS | N23: 029 | AC23: =+O23-AA23-AB23 -> 0
B24: ¿Sujeto pasivo exento de aplicación del régimen de precios de transferencia? | N24: 30 | O24: =SUMIF('1 BL anterior'!A:A,N24,'1 BL anterior'!E:E) -> 0 | AC24: =+O24-AA24-AB24 -> 0
A25: ESTADO DE SITUACIÓN FINANCIERA | AC25: =+O25-AA25-AB25 -> 0
B26: ACTIVO | AC26: =+O26-AA26-AB26 -> 0
C27: ACTIVOS CORRIENTES | AC27: =+O27-AA27-AB27 -> 0
D28: Efectivo y equivalentes al efectivo | N28: 311 | O28: =SUMIF('1 BL anterior'!B:B,N28,'1 BL anterior'!E:E) -> 21075.33 | AB28: 4632.67 | AC28: =+O28-AA28-AB28 -> 16442.66
D29: CUENTAS Y DOCUMENTOS POR COBRAR CORRIENTES | AC29: =+O29-AA29-AB29 -> 0
E30: CUENTAS Y DOCUMENTOS POR COBRAR COMERCIALES CORRIENTES | AC30: =+O30-AA30-AB30 -> 0
F31: RELACIONADAS | AC31: =+O31-AA31-AB31 -> 0
A32: ______ | B32: ______ | C32: ______ | D32: ______ | E32: ______ | F32: ______ | G32: Locales | N32: 312 | O32: =SUMIF('1 BL anterior'!B:B,N32,'1 BL anterior'!E:E) -> 0 | AC32: =+O32-AA32-AB32 -> 0
G33: Del exterior | N33: 313 | O33: =SUMIF('1 BL anterior'!B:B,N33,'1 BL anterior'!E:E) -> 0 | AC33: =+O33-AA33-AB33 -> 0
G34: (-) Deterioro acumulado del valor de cuentas y documentos por cobrar comerciales por incobrabilidad (provisiones para créditos incobrables) | N34: 314 | O34: =SUMIF('1 BL anterior'!B:B,N34,'1 BL anterior'!E:E) -> 0 | AC34: =+O34-AA34-AB34 -> 0
F35: NO RELACIONADAS | AC35: =+O35-AA35-AB35 -> 0
G36: Locales | N36: 315 | O36: =SUMIF('1 BL anterior'!B:B,N36,'1 BL anterior'!E:E) -> 0 | AC36: =+O36-AA36-AB36 -> 0
G37: Del exterior | N37: 316 | O37: =SUMIF('1 BL anterior'!B:B,N37,'1 BL anterior'!E:E) -> 0 | AC37: =+O37-AA37-AB37 -> 0
G38: (-) Deterioro acumulado del valor de cuentas y documentos por cobrar comerciales por incobrabilidad (provisiones para créditos incobrables) | N38: 317 | O38: =SUMIF('1 BL anterior'!B:B,N38,'1 BL anterior'!E:E) -> 0 | Q38: exceder del 10% de la cartera total. | R38: .- Las provisiones para créditos incobrables originados en operaciones del giro ordinario del negocio, efectuadas en cada ejercicio impositivo a razón del 1% anual sobre los créditos comerciales concedidos en dicho ejercicio y que se encuentren pendientes de recaudación al cierre del mismo, sin que la provisión acumulada pueda exceder del 10% de la cartera total. | AC38: =+O38-AA38-AB38 -> 0
E39: OTRAS CUENTAS Y DOCUMENTOS POR COBRAR CORRIENTES | AC39: =+O39-AA39-AB39 -> 0
F40: A ACCIONISTAS, SOCIOS, PARTICIPES, BENEFICIARIOS U OTROS TITULARES DE DERECHOS REPRESENTATIVOS DE CAPITAL | AC40: =+O40-AA40-AB40 -> 0
G41: Locales | N41: 318 | O41: =SUMIF('1 BL anterior'!B:B,N41,'1 BL anterior'!E:E) -> 0 | AC41: =+O41-AA41-AB41 -> 0
...

