Workbook

Sheet A- Control Info Societaria
E1: 3 A.N.G ADMINISTRACION DE NEGOCIOS GERENCIALES CÍA. LTDA.
E2: CONOCIMIENTO DEL NEGOCIO
E3: A- Control Interno - Información Societaria
E4: COMPAÑÍA: | F4: TABACALERA MENHURSA S.A.
E5: PERÍODO AUDITADO: | F5: Del 01 de enero a 31 de diciembre del 2023
E6: ELABORADO POR: | F6: Kely Balarezo | H6: FECHA: | I6: 45198 | J6: Firma y sello
E7: REVISADO POR: | F7: Elizabeth Palacios | H7: FECHA: | I7: =+I6+3 -> 45201 | J7: APROBADO: R.C.
B8: CUMPLIMIENTO
B9: X | C9: 0 | D9: No Cumple. | J9: Papel de Trbajo Actualizado al 24 de agosto del 2023
B10: ✔ | C10: 1 | D10: Si Cumple. | F10: Instrucciones:
B11: N/A | C11: 0 | D11: No Aplica. | F11: Debe llenar todos los campos, los items no llenados o vacíos se califican como incumplimiento
B13: REF | D13: DESCRIPCIÓN | F13: FECHA DE ACTUALIZACIÓN | H13: PERÍODO AUDITADO 2022 | I13: PERÍODOS ANTERIORES | J13: OBSERVACIÓN
F14: COMPAÑÍA | G14: AUDITOR 3ANG | N14: Ponderación | Q14: N/A
A15: ¿¿ | B15: A- | C15: 01. | D15: Ruc de la Compañía. | F15: 44713 | G15: 45198 | H15: ✔ | N15: =SUMIF(H15,B$10,C$10) -> 1 | Q15: =SUMIF(H15,B$11,C$10) -> 0
A16: ¿¿ | B16: A- | C16: 02. | D16: RUP De la Compañía. | H16: N/A | N16: =SUMIF(H16,B$10,C$10) -> 0 | Q16: =SUMIF(H16,B$11,C$10) -> 1
A17: ¿¿ | B17: A- | C17: 03. | D17: Escrituras de Constitución. | F17: 44092 | G17: 45198 | H17: ✔ | N17: =SUMIF(H17,B$10,C$10) -> 1 | Q17: =SUMIF(H17,B$11,C$10) -> 0
A18: ¿¿ | B18: A- | C18: 04. | D18: Aumento de Capital. Y Aumento de Reservas. | H18: N/A | N18: =SUMIF(H18,B$10,C$10) -> 0 | Q18: =SUMIF(H18,B$11,C$10) -> 1
A19: ¿¿ | B19: A- | C19: 05. | D19: Nómina de Socios o Accionistas. | F19: 45195 | G19: 45198 | H19: ✔ | N19: =SUMIF(H19,B$10,C$10) -> 1 | Q19: =SUMIF(H19,B$11,C$10) -> 0
B20: A- | C20: 06. | D20: Transferencia de Acciones | H20: N/A | N20: =SUMIF(H20,B$10,C$10) -> 0 | Q20: =SUMIF(H20,B$11,C$10) -> 1
A21: ¿¿ | B21: A- | C21: 07. | D21: Nombramiento de Administradores.
A22: ¿¿ | D22: .1. | E22: Gerente. | F22: 44092 | G22: 45198 | H22: ✔ | N22: =SUMIF(H22,B$10,C$10) -> 1 | Q22: =SUMIF(H22,B$11,C$10) -> 0
A23: ¿¿ | D23: .2. | E23: Presidente. | F23: 44092 | G23: 45198 | H23: ✔ | N23: =SUMIF(H23,B$10,C$10) -> 1 | Q23: =SUMIF(H23,B$11,C$10) -> 0
A24: ¿¿ | B24: A- | C24: 08. | D24: Apoderado Especial. | H24: N/A | N24: =SUMIF(H24,B$10,C$10) -> 0 | Q24: =SUMIF(H24,B$11,C$10) -> 1
A25: ¿¿ | B25: A- | C25: 09. | D25: Informe del gerente y comisario
D26: .1. | E26: Informe del Gerente | F26: 45156 | G26: 45198 | H26: ✔ | N26: =SUMIF(H26,B$10,C$10) -> 1 | Q26: =SUMIF(H26,B$11,C$10) -> 0
D27: .2. | E27: Informe del Comisario | F27: 45156 | G27: 45198 | H27: ✔ | N27: =SUMIF(H27,B$10,C$10) -> 1 | Q27: =SUMIF(H27,B$11,C$10) -> 0
A28: ¿¿ | B28: A- | C28: 10. | D28: Auditoría externa períodos Anteriores.
D29: .1. | E29: Informe periodos anteriores | F29: 45156 | G29: 45198 | H29: ✔ | N29: =SUMIF(H29,B$10,C$10) -> 1 | Q29: =SUMIF(H29,B$11,C$10) -> 0
D30: .2. | E30: Recomendaciones periodos anteriores | F30: 45168 | G30: 45198 | H30: ✔ | N30: =SUMIF(H30,B$10,C$10) -> 1 | Q30: =SUMIF(H30,B$11,C$10) -> 0
A31: ¿¿ | B31: A- | C31: 11. | D31: Informe Lav. Activos período Anterior. | H31: N/A | N31: =SUMIF(H31,B$10,C$10) -> 0 | Q31: =SUMIF(H31,B$11,C$10) -> 1
A32: ¿¿ | B32: A- | C32: 12. | D32: Otros Informes. | H32: N/A | N32: =SUMIF(H32,B$10,C$10) -> 0 | Q32: =SUMIF(H32,B$11,C$10) -> 1
A33: ¿¿ | B33: A- | C33: 13. | D33: Certificaciones de calidad. | H33: X | J33: PENDIENTE | N33: =SUMIF(H33,B$10,C$10) -> 0 | Q33: =SUMIF(H33,B$11,C$10) -> 0
A34: ¿¿ | B34: A- | C34: 14. | D34: Contratos Significativos Vigentes
D35: .1. | E35: Principales Clientes | H35: X | J35: PENDIENTE | N35: =SUMIF(H35,B$10,C$10) -> 0 | Q35: =SUMIF(H35,B$11,C$10) -> 0
D36: .2. | E36: Principales Proveedores | H36: X | J36: PENDIENTE | N36: =SUMIF(H36,B$10,C$10) -> 0 | Q36: =SUMIF(H36,B$11,C$10) -> 0
A37: ¿¿ | B37: A- | C37: 15. | D37: Contratos por Patentes y Regalias. | H37: X | J37: PENDIENTE | N37: =SUMIF(H37,B$10,C$10) -> 0 | Q37: =SUMIF(H37,B$11,C$10) -> 0
A38: ¿¿ | B38: A- | C38: 16. | D38: Contratos de Arrendamientos. | H38: X | J38: PENDIENTE | N38: =SUMIF(H38,B$10,C$10) -> 0 | Q38: =SUMIF(H38,B$11,C$10) -> 0
A39: ¿¿ | B39: A- | C39: 17. | D39: Contratos de Asesores Legales-Tributarios. | H39: X | J39: PENDIENTE | N39: =SUMIF(H39,B$10,C$10) -> 0 | Q39: =SUMIF(H39,B$11,C$10) -> 0
A40: ¿¿ | B40: A- | C40: 18. | D40: Contratos de Seguros. | H40: X | J40: PENDIENTE | N40: =SUMIF(H40,B$10,C$10) -> 0 | Q40: =SUMIF(H40,B$11,C$10) -> 0
A41: ¿¿ | B41: A- | C41: 19. | D41: Hoja Membretada de la compañía | H41: X | J41: PENDIENTE | N41: =SUMIF(H41,B$10,C$10) -> 0 | Q41: =SUMIF(H41,B$11,C$10) -> 0
...

Sheet B- Control Admin-Organizacional
E1: 3 A.N.G ADMINISTRACION DE NEGOCIOS GERENCIALES CÍA. LTDA.
E2: CONOCIMIENTO DEL NEGOCIO
E3: B- Control Administrativo - Organizacional
E4: COMPAÑÍA: | F4: =+'A- Control Info Societaria'!F4 -> TABACALERA MENHURSA S.A.
E5: PERÍODO AUDITADO: | F5: =+'A- Control Info Societaria'!F5 -> Del 01 de enero a 31 de diciembre del 2023
E6: REVISADO POR: | F6: =+'A- Control Info Societaria'!F6 -> Kely Balarezo | H6: FECHA: | I6: =+'A- Control Info Societaria'!I6 -> 45198 | J6: Firma y sello
E7: SUPERVISADO POR: | F7: =+'A- Control Info Societaria'!F7 -> Elizabeth Palacios | H7: FECHA: | I7: =+I6+3 -> 45201 | J7: APROBADO: R.C.
B8: CUMPLIMIENTO | J8: Papel de Trbajo Actualizado al 24 de agosto del 2023
B9: X | C9: 0 | D9: No Cumple.
B10: ✔ | C10: 1 | D10: Si Cumple. | F10: Instrucciones:
B11: N/A | C11: 0 | D11: No Aplica. | F11: Debe llenar todos los campos, los items no llenados o vacíos se califican como incumplimiento
B13: REF | D13: DESCRIPCIÓN | F13: FECHA DE ACTUALIZACIÓN | H13: PERÍODO AUDITADO 2022 | I13: PERÍODOS ANTERIORES | J13: OBSERVACIÓN
F14: COMPAÑÍA | G14: AUDITOR 3ANG | N14: Ponderación | Q14: N/A
A15: ¿¿ | B15: B- | C15: 01 | D15: Manual de Funciones- Organigramas de la Compañía. | H15: X | J15: PENDIENTE | N15: =SUMIF(H15,B$10,C$10) -> 0 | Q15: =SUMIF(H15,B$11,C$10) -> 0
A16: ¿¿ | B16: B- | C16: 02. | D16: Manual de Procesos y Operaciones | H16: X | J16: PENDIENTE | N16: =SUMIF(H16,B$10,C$10) -> 0 | Q16: =SUMIF(H16,B$11,C$10) -> 0
B17: B- | C17: 03. | D17: Otros Manuales | H17: X | J17: PENDIENTE | N17: =SUMIF(H17,B$10,C$10) -> 0 | Q17: =SUMIF(H17,B$11,C$10) -> 0
A18: ¿¿ | B18: B- | C18: 04. | D18: Libros Societarios.
D19: 1. | E19: Libro de actas. | F19: 45195 | G19: 45198 | H19: ✔ | N19: =SUMIF(H19,B$10,C$10) -> 1 | Q19: =SUMIF(H19,B$11,C$10) -> 0
D20: 2. | E20: Libro de expedientes. | H20: X | J20: PENDIENTE | N20: =SUMIF(H20,B$10,C$10) -> 0 | Q20: =SUMIF(H20,B$11,C$10) -> 0
D21: 3. | E21: Libro de Participaciones. | H21: X | J21: PENDIENTE | N21: =SUMIF(H21,B$10,C$10) -> 0 | Q21: =SUMIF(H21,B$11,C$10) -> 0
D22: 4. | E22: Libro de certificado de Aportaciones | H22: X | J22: PENDIENTE | N22: =SUMIF(H22,B$10,C$10) -> 0 | Q22: =SUMIF(H22,B$11,C$10) -> 0
A23: ¿¿ | B23: B- | C23: 05. | D23: Reglamento Interno de Trabajo. | H23: X | J23: PENDIENTE | N23: =SUMIF(H23,B$10,C$10) -> 0 | Q23: =SUMIF(H23,B$11,C$10) -> 0
A24: ¿¿ | B24: B- | C24: 06. | D24: Reglamento de Contratación de Empleados. | H24: X | J24: PENDIENTE | N24: =SUMIF(H24,B$10,C$10) -> 0 | Q24: =SUMIF(H24,B$11,C$10) -> 0
A25: ¿¿ | B25: B- | C25: 07. | D25: Reglamento de Higiene y Seguridad (+10 trab). | H25: X | J25: PENDIENTE | N25: =SUMIF(H25,B$10,C$10) -> 0 | Q25: =SUMIF(H25,B$11,C$10) -> 0
A26: ¿¿ | B26: B- | C26: 08. | D26: Plan de Contingencia y otros | H26: X | J26: PENDIENTE | N26: =SUMIF(H26,B$10,C$10) -> 0 | Q26: =SUMIF(H26,B$11,C$10) -> 0
A27: ¿¿ | B27: B- | C27: 09. | D27: Conformación de Organismos Paritarios. | H27: X | J27: PENDIENTE | N27: =SUMIF(H27,B$10,C$10) -> 0 | Q27: =SUMIF(H27,B$11,C$10) -> 0
A28: ¿¿ | B28: B- | C28: 10. | D28: Otros Organismos. | H28: X | J28: PENDIENTE | N28: =SUMIF(H28,B$10,C$10) -> 0 | Q28: =SUMIF(H28,B$11,C$10) -> 0
A29: ¿¿ | B29: B- | C29: 11. | D29: Estudios Actuariales. | H29: X | J29: PENDIENTE | N29: =SUMIF(H29,B$10,C$10) -> 0 | Q29: =SUMIF(H29,B$11,C$10) -> 0
A30: ¿¿ | B30: B- | C30: 12. | D30: Codigo de Etica Aprobado | H30: X | J30: PENDIENTE | N30: =SUMIF(H30,B$10,C$10) -> 0 | Q30: =SUMIF(H30,B$11,C$10) -> 0
A31: 16 | B31: B- | C31: 13. | D31: Reglamento Interno de Mercado de Valores | H31: N/A | N31: =SUMIF(H31,B$10,C$10) -> 0 | Q31: =SUMIF(H31,B$11,C$10) -> 1
A32: ¿¿ | B32: B- | C32: 14. | D32: Contrato Salud Ocupacional | H32: X | J32: PENDIENTE | N32: =SUMIF(H32,B$10,C$10) -> 0
N33: =SUM(N15:N31) -> 1 | Q33: =SUM(Q15:Q31) -> 1 | R33: =+A31-Q33 -> 15
B34: NOTA FINAL:
G35: CUMPLIMIENTO | H35: =+N33/R33 -> 0.066666667

Sheet C- Control Contable Financiero
E1: 3 A.N.G ADMINISTRACION DE NEGOCIOS GERENCIALES CÍA. LTDA.
E2: CONOCIMIENTO DEL NEGOCIO
E3: C- Control Contable y Financiero.
E4: COMPAÑÍA: | F4: =+'B- Control Admin-Organizacional'!F4 -> TABACALERA MENHURSA S.A.
E5: PERÍODO AUDITADO: | F5: =+'B- Control Admin-Organizacional'!F5 -> Del 01 de enero a 31 de diciembre del 2023 | J5: APROBADO POR: R.C.
E6: ELABORADO POR: | F6: =+'B- Control Admin-Organizacional'!F6 -> Kely Balarezo | H6: FECHA: | I6: =+'B- Control Admin-Organizacional'!I6 -> 45198 | J6: Firma y sello
E7: REVISADO POR: | F7: =+'B- Control Admin-Organizacional'!F7 -> Elizabeth Palacios | H7: FECHA: | I7: =+I6+3 -> 45201
B8: CUMPLIMIENTO | J8: Papel de Trbajo Actualizado al 24 de agosto del 2023
B9: X | D9: No Cumple.
B10: ✔ | C10: 1 | D10: Si Cumple. | F10: Instrucciones:
B11: N/A | D11: No Aplica. | F11: Debe llenar todos los campos, los items no llenados o vacíos se califican como incumplimiento
B13: REF | D13: DESCRIPCIÓN | F13: FECHA DE ACTUALIZACIÓN | H13: PERÍODO AUDITADO 2022 | I13: PERÍODOS ANTERIORES | J13: OBSERVACIÓN
F14: COMPAÑÍA | G14: AUDITOR 3ANG | M14: Ponderación | Q14: N/A
A15: ¿¿ | B15: C- | C15: 01 | D15: Políticas, Contables y Presupuestarias. | H15: X | J15: PENDIENTE | M15: =SUMIF(H15,B$10,C$10) -> 0 | Q15: =SUMIF(H15,B$11,C$10) -> 0
A16: ¿¿ | B16: C- | C16: 02. | D16: Políticas Financieras -Crédito. | H16: X | J16: PENDIENTE | M16: =SUMIF(H16,B$10,C$10) -> 0 | Q16: =SUMIF(H16,B$11,C$10) -> 0
A17: ¿¿ | B17: C- | C17: 03. | D17: Manual de funciones del Sistema Contable.
D18: 1. | E18: Módulos, Pantallas de uso del sistema. | H18: X | J18: PENDIENTE | M18: =SUMIF(H18,B$10,C$10) -> 0 | Q18: =SUMIF(H18,B$11,C$10) -> 0
D19: 2. | E19: Contrato de prestación del servicio. | H19: X | J19: PENDIENTE | M19: =SUMIF(H19,B$10,C$10) -> 0 | Q19: =SUMIF(H19,B$11,C$10) -> 0
D20: 3. | E20: Información del Sistema Contable (cuadro ICT). | H20: X | J20: PENDIENTE | M20: =SUMIF(H20,B$10,C$10) -> 0 | Q20: =SUMIF(H20,B$11,C$10) -> 0
A21: ¿¿ | B21: C- | C21: 04. | D21: Plan de cuentas. | H21: X | J21: PENDIENTE | M21: =SUMIF(H21,B$10,C$10) -> 0 | Q21: =SUMIF(H21,B$11,C$10) -> 0
A22: ¿¿ | B22: C- | C22: 05. | D22: Notas a los Estados Financieros. | F22: 45156 | G22: 45198 | H22: ✔ | M22: =SUMIF(H22,B$10,C$10) -> 1 | Q22: =SUMIF(H22,B$11,C$10) -> 0
A23: ¿¿ | B23: C- | C23: 06. | D23: Estados Financieros del período anterior.
A24: ¿¿ | D24: .1. | E24: Estado de Situación Financiera. | F24: 45195 | G24: 45198 | H24: ✔ | M24: =SUMIF(H24,B$10,C$10) -> 1 | Q24: =SUMIF(H24,B$11,C$10) -> 0
D25: .2. | E25: Flujos de Efectivo. | F25: 45195 | G25: 45198 | H25: ✔ | M25: =SUMIF(H25,B$10,C$10) -> 1 | Q25: =SUMIF(H25,B$11,C$10) -> 0
D26: .3. | E26: Estado de Cambios en el Patrimonio. | F26: 45195 | G26: 45198 | H26: ✔ | M26: =SUMIF(H26,B$10,C$10) -> 1 | Q26: =SUMIF(H26,B$11,C$10) -> 0
A27: ¿¿ | D27: .4. | E27: Formulario 101 (desde la fecha de constitución). | F27: 45163 | G27: 45198 | H27: ✔ | M27: =SUMIF(H27,B$10,C$10) -> 1 | Q27: =SUMIF(H27,B$11,C$10) -> 0
A28: ¿¿ | B28: C- | C28: 07. | D28: Estados Financieros del Período Auditado.
D29: .1. | E29: Estado de Situación Financiera. | H29: X | J29: PENDIENTE | M29: =SUMIF(H29,B$10,C$10) -> 0 | Q29: =SUMIF(H29,B$11,C$10) -> 0
D30: .2. | E30: Flujos de Efectivo. | H30: X | J30: PENDIENTE | M30: =SUMIF(H30,B$10,C$10) -> 0 | Q30: =SUMIF(H30,B$11,C$10) -> 0
D31: .3. | E31: Estado de Cambios en el Patrimonio. | H31: X | J31: PENDIENTE | M31: =SUMIF(H31,B$10,C$10) -> 0 | Q31: =SUMIF(H31,B$11,C$10) -> 0
D32: .4. | E32: Formulario 101 (período auditado). | H32: X | J32: PENDIENTE | M32: =SUMIF(H32,B$10,C$10) -> 0 | Q32: =SUMIF(H32,B$11,C$10) -> 0
A33: ¿¿ | B33: C- | C33: 08. | D33: Mapeo Form 101. Año Anterior. | F33: 44926 | G33: 45198 | H33: ✔ | M33: =SUMIF(H33,B$10,C$10) -> 1 | Q33: =SUMIF(H33,B$11,C$10) -> 0
A34: ¿¿ | B34: C- | C34: 09. | D34: Listado de Bancos y operaciones | H34: X | J34: PENDIENTE | M34: =SUMIF(H34,B$10,C$10) -> 0 | Q34: =SUMIF(H34,B$11,C$10) -> 0
A35: ¿¿ | B35: C- | C35: 10. | D35: Informe de Cumplimiento Tributario ICT periodo Anterior.
D36: .1. | E36: Anexos. | F36: 45168 | G36: 45198 | H36: ✔ | M36: =SUMIF(H36,B$10,C$10) -> 1 | Q36: =SUMIF(H36,B$11,C$10) -> 0
D37: .2. | E37: Opinión. | F37: 45168 | G37: 45198 | H37: ✔ | M37: =SUMIF(H37,B$10,C$10) -> 1 | Q37: =SUMIF(H37,B$11,C$10) -> 0
D38: .3. | E38: Recomendaciones Tributarias. | F38: 45168 | G38: 45198 | H38: ✔ | M38: =SUMIF(H38,B$10,C$10) -> 1 | Q38: =SUMIF(H38,B$11,C$10) -> 0
A39: ¿¿ | B39: C- | C39: 11. | D39: Popiedad Planta y Equipo.
D40: .1. | E40: Cuadro de Activos Fijos | H40: X | J40: PENDIENTE | M40: =SUMIF(H40,B$10,C$10) -> 0 | Q40: =SUMIF(H40,B$11,C$10) -> 0
D41: .2. | E41: Escrituras de terrenos | H41: X | J41: PENDIENTE | M41: =SUMIF(H41,B$10,C$10) -> 0 | Q41: =SUMIF(H41,B$11,C$10) -> 0
...
