Workbook

Sheet RECOPILACIÓN
C1: RECOPILACIÓN DATOS GENERALES DEL CLIENTE
C2: PERIODO: Del 01 de enero al 31 de Diciembre del 2023
C3: ÁREA: | D3: Control Interno | F3: Fecha
C4: ELABORADO POR: | D4: Kely Balarezo | F4: 45198
C5: REVISADO | D5: Roy Cisneros | F5: 0
C6: APROBADO POR: | D6: Roy Cisneros | F6: 0
F7: Papel de Trabajo actualizado septiembre-2022
B9: 1 | C9: NOMBRE EMPRESA: | D9: TABACALERA MENHURSA S.A.
B10: 2 | C10: FECHA DE CONSTITUCIÓN: | D10: 44095
B11: 3 | C11: TIPO DE SOCIEDAD: | D11: Sociedad Anónima
B12: 4 | C12: NÚMERO DE RUC: | D12: 1291784468001
B13: 5 | C13: CANTIDAD DE SOCIOS: | D13: 3
B14: 6 | C14: APORTE DE SOCIOS: | D14: 800
B15: 7 | C15: DIRECCIÓN: | D15: Buena Fé, Avenida 7 de agosto - Recinto Federico Intriago
B16: 8 | C16: CANTIDAD DE SUCURSALES: | D16: -
B17: 9 | C17: TELÉFONOS: | D17: 0939027611 - 052951049
B18: 10 | C18: EMAIL: | D18: edumendoza3095@gmail.com
B19: 11 | C19: PAGINA WEB: | D19: -
B20: 12 | C20: NOMBRE DEL PRESIDENTE DE LA CIA: | D20: MENDOZA PALMA ERWIN EDUARDO
B21: 13 | C21: NOMBRE DEL GERENTE GENERAL: | D21: MENDOZA HURTADO EDUARDO ISRAEL
B22: 14 | C22: NOMBRE DEL APODERADO: | D22: -
B23: 15 | C23: NOMBRE JEFE DE CONTABILIDAD | D23: SOLORZANO MONCADA ALFONSO PROSPERO
B24: 16 | C24: NOMBRE JEFE DE COMPRAS
B25: 17 | C25: NOMBRE JEFE DE VENTAS
B26: 18 | C26: NOMBRE DE ABOGADO ASESOR
B27: 19 | C27: DETALLE DE EJECUTIVOS IMPORTANTES
B30: 20 | C30: ESTADOS FINANCIEROS:
B31: 21 | C31: ACTIVOS TOTAL
B32: 22 | C32: PASIVOS TOTAL
B33: 23 | C33: PATRIMONIO
B34: 24 | C34: INGRESOS
B35: 25 | C35: GASTOS
B36: 26 | C36: UTILIDAD O PERDIDA
B37: 27 | C37: IMPUESTO A LA RENTA PAGADO
... B41: 31 | C41: DETALLE DE LITIGIOS EN CONTRA
C42: NOTA FINAL:
C45: Elaborado por: | D45: ____________________________________________________________

Sheet REDACCIÓN
C2: EMPRESA: | D2: =+RECOPILACIÓN!D9 -> TABACALERA MENHURSA S.A.
C3: PERÍODO: | D3: =+CUESTIONARIO!E3 -> Del 01 de enero al 31 de diciembre del 2023
C4: ELABORADO: | F4: FECHA:
C5: REVISADO: | F5: FECHA:
C6: APROBADO | F6: FECHA:
F7: =+RECOPILACIÓN!F7 -> Papel de Trabajo actualizado septiembre-2022
A8: ¿¿¿¿¿ | B8: El conocimiento del negocio, constituye un requisito fundamental para entender e identificar las actividades, operaciones y negocios de la empresa, su naturaleza, antecedentes, tamaño, organización, objetivos, negocios principales, programas de inversión y crecimientos, proyectos, estrategias, riesgos, ambiente de control, y controles internos establecidos a fin de facilitar el desarrollo de la auditoría.
B10: Requerimientos
B11: 1. | C11: Información Básica.
B18: 2. | C18: Misión de la Entidad.
B25: 3. | C25: Descripción breve de las funciones, atribuciones y competencias de la entidad.
B32: 4. | C32: Principales Líneas de autoridad
B39: 5. | C39: Organigama, departamentos de la compañía
B46: 6. | C46: Préstamos Recibidos
B53: 7. | C53: Contratos con el estado
B60: 8. | C60: Contingencias, litigios o reclamaciones.
B67: 10. | C67: Información de la Auditoría anterior
B74: 11. | C74: Comercialización-compras
B81: 12. | C81: Comercialización - ingresos
B88: 13. | C88: Políticas de crédito y Cobranzas
... B121: 18. | C121: Principales productos y servicios que ofrece

Sheet CUESTIONARIO
B1: CUESTIONARIO DE AUDITORÍA SOBRE EL CONTROL INTERNO
B2: COMPAÑÍA: | E2: =+REDACCIÓN!D2 -> TABACALERA MENHURSA S.A.
B3: PERÍODO: | E3: Del 01 de enero al 31 de diciembre del 2023
B4: ÁREA: | E4: Control Interno
B5: ELABORADO POR: | E5: ********** | H5: FECHA:
B6: REVISADO | E6: Roy Cisneros | H6: FECHA: | L6: APROBADO: R.C.
B7: CUMPLIMIENTO | E7: CALIFICACIÓN | G7: RESPUESTA BASADA EN | L7: Firma y sello
B8: X | D8: No Cumple. | E8: 0 | G8: Pregunta
B9: ✔ | D9: Si Cumple. | E9: 1 | G9: Observación
B10: N/A | D10: No Aplica. | E10: - | G10: Otra | L10: =+REDACCIÓN!F7 -> Papel de Trabajo actualizado septiembre-2022
B11: INSTRUCCIONES | E11: * Debe llenar todos los campos, los items no llenados o vacíos se califican como incumplimiento
B12: OBJETIVOS: | E12: * Obtener un entendimiento global del control interno y del entorno contable y financiero de la compañía.
E13: * Valorar el entorno de control como parte del enfoque de la Auditoria.
E14: * Obtener evidencia sobre los controles internos en vistas a valorar si se puede confiar en ellos.
B15: REF | C15: N° | D15: PREGUNTA | H15: AÑO ACTUAL | I15: PERÍODOS ANTERIORES | J15: RESPUESTA BASADA EN | K15: CAL | L15: OBSERVACIÓN | R15: N/A
B16: ACTIVIDAD | K16: =SUMIF(H16,B$9,E$9) -> 0 | R16: =SUMIF(H16:H111,B$10,E$9) -> 0
C17: 1 | D17: ¿Están las actividades que desarrolla la compañía inscritas en el RUC? | K17: =SUMIF(H17,B$9,E$9) -> 0 | R17: =SUMIF(H17:H112,B$10,E$9) -> 0
A18: ¿ | C18: 2 | D18: ¿La dirección que consta en el RUC es en la que funciona la compañía? | K18: =SUMIF(H18,B$9,E$9) -> 0 | R18: =SUMIF(H18:H113,B$10,E$9) -> 0
C19: 3 | D19: ¿Está el nombramiento del gerente y presidente actualizados? | K19: =SUMIF(H19,B$9,E$9) -> 0 | R19: =SUMIF(H19:H114,B$10,E$9) -> 0
B20: ACTAS Y CONTRATOS | K20: =SUMIF(H20,B$9,E$9) -> 0 | R20: =SUMIF(H20:H115,B$10,E$9) -> 0
A21: ¿ | C21: 4 | D21: ¿Cuenta la empresa con un libro de Acciones y Accionistas? | H21: X | K21: =SUMIF(H21,B$9,E$9) -> 0 | R21: =SUMIF(H21:H116,B$10,E$9) -> 0
A22: ¿¿¿ | C22: 5 | D22: ¿La compañía maneja un libro de actas cumpliendo las disposiciones del art. 122 de la ley de compañías y el art. 34 del Reglamento de Junta General de Socios y Accionistas.? | H22: ✔ | K22: =SUMIF(H22,B$9,E$9) -> 1 | R22: =SUMIF(H22:H117,B$10,E$9) -> 0
A23: ¿¿ | C23: 6 | D23: ¿Existen contratos importantes celebrados por la compañía y vigentes en el periodo de la auditoria? | K23: =SUMIF(H23,B$9,E$9) -> 0 | R23: =SUMIF(H23:H118,B$10,E$9) -> 0
A24: ¿ | C24: 7 | D24: Se celebran regularmente sesiones del Consejo de Administración. | K24: =SUMIF(H24,B$9,E$9) -> 0 | R24: =SUMIF(H24:H119,B$10,E$9) -> 0
A25: ¿ | C25: 8 | D25: Constan todas las actas en los libros respectivos y están firmadas. | K25: =SUMIF(H25,B$9,E$9) -> 0 | R25: =SUMIF(H25:H120,B$10,E$9) -> 0
A26: ¿¿ | C26: 9 | D26: En las actas de asambleas generales de accionistas que deciden sobre los resultados anuales, se hacen constar las cifras en cada caso. | K26: =SUMIF(H26,B$9,E$9) -> 0 | R26: =SUMIF(H26:H121,B$10,E$9) -> 0
B27: ORGANIZACIÓN | K27: =SUMIF(H27,B$9,E$9) -> 0 | R27: =SUMIF(H27:H122,B$10,E$9) -> 0
C28: 10 | D28: ¿Existe un Código de Ética aprobado por la entidad? | K28: =SUMIF(H28,B$9,E$9) -> 0 | R28: =SUMIF(H28:H123,B$10,E$9) -> 0
A29: ¿¿ | C29: 11 | D29: ¿La empresa cuenta con un manual de políticas, procedimientos y descripción de funciones? | K29: =SUMIF(H29,B$9,E$9) -> 0 | R29: =SUMIF(H29:H124,B$10,E$9) -> 0
A30: ¿¿¿ | C30: 12 | D30: ¿Tiene el cliente organigramas generales, por departamento, se encuentran actualizados, se cuenta con evidencia de publicación y difusión? | K30: =SUMIF(H30,B$9,E$9) -> 0 | R30: =SUMIF(H30:H125,B$10,E$9) -> 0
A31: ¿¿¿¿ | C31: 13 | D31: ¿Existen normas y procedimientos para la contratación, adiestramiento, motivación, evaluación, promoción, remuneración, traslados y terminación de personal que sean aplicables a todas las áreas funcionales. | K31: =SUMIF(H31,B$9,E$9) -> 0 | R31: =SUMIF(H31:H126,B$10,E$9) -> 0
C32: 14 | D32: ¿ La compañía auditada generó ingresos operacionales ? | K32: =SUMIF(H32,B$9,E$9) -> 0 | R32: =SUMIF(H32:H127,B$10,E$9) -> 0
A33: ¿¿ | C33: 15 | D33: ¿Existe y se aplica política para cuentas incobrables o de difícil recuperación. | K33: =SUMIF(H33,B$9,E$9) -> 0 | R33: =SUMIF(H33:H128,B$10,E$9) -> 0
B34: JUICIOS LEGALES | K34: =SUMIF(H34,B$9,E$9) -> 0 | R34: =SUMIF(H34:H129,B$10,E$9) -> 0
A35: ¿ | C35: 16 | D35: ¿Cuenta el cliente con abogados internos o externos? | K35: =SUMIF(H35,B$9,E$9) -> 0 | R35: =SUMIF(H35:H130,B$10,E$9) -> 0
A36: ¿¿¿¿ | C36: 17 | D36: ¿Se mantiene un archivo o un registro en donde cuenten todos los datos relativos a: - Juicios de cualquier clase. - Contratos, convenios y compromisos - Poderes otorgados - Cuentas por cobrar entregadas a los abogados? | K36: =SUMIF(H36,B$9,E$9) -> 0 | R36: =SUMIF(H36:H131,B$10,E$9) -> 0
A37: ¿ | C37: 18 | D37: ¿La empresa está libre de juicioso litigios? | K37: =SUMIF(H37,B$9,E$9) -> 0 | R37: =SUMIF(H37:H132,B$10,E$9) -> 0
B38: SISTEMAS, LIBROS, NIIF | K38: =SUMIF(H38,B$9,E$9) -> 0 | R38: =SUMIF(H38:H133,B$10,E$9) -> 0
A39: ¿¿ | C39: 19 | D39: ¿Se preparan presupuestos y en su caso se comparan mensualmente contra cifras reales.? | K39: =SUMIF(H39,B$9,E$9) -> 0 | R39: =SUMIF(H39:H134,B$10,E$9) -> 0
A40: ¿ | C40: 20 | D40: ¿Se encuentran debidamente autorizados? | K40: =SUMIF(H40,B$9,E$9) -> 0 | R40: =SUMIF(H40:H135,B$10,E$9) -> 0
...

Sheet PLANIFICACIÓN
B1: PLANIFICACIÓN SOBRE EL CONTROL INTERNO
B2: COMPAÑÍA: | E2: =+CUESTIONARIO!E2 -> TABACALERA MENHURSA S.A.
B3: PERÍODO: | E3: Del 01 de enero al 31 de diciembre del 2023
B4: ÁREA: | E4: Control Interno
B5: ELABORADO POR: | E5: ***** | H5: FECHA:
B6: SUPERVISADO POR: | E6: Roy Cisneros | H6: FECHA:
B7: CUMPLIMIENTO | E7: CALIFICACIÓN | G7: RESPUESTA BASADA EN | J7: REVISADO: R.C.
B8: X | D8: No Cumple. | E8: 0 | G8: Pregunta
B9: ✔ | D9: Si Cumple. | E9: 1 | G9: Observación | J9: Firma y sello
B10: N/A | D10: No Aplica. | E10: - | G10: Otra
B12: OBJETIVOS: | D12: * Obtener un entendimiento global del control interno y del entorno contable y financiero de la compañía.
D13: * Valorar el entorno de control como parte del enfoque de la Auditoria.
D14: * Obtener evidencia sobre los controles internos en vistas a valorar si se puede confiar en ellos.
C15: PROCEDIMIENTOS A SEGUIR | H15: =+CUESTIONARIO!L10 -> Papel de Trabajo actualizado septiembre-2022
A16: ¿ | B16: 1 | C16: Revisar las Actividades del Ruc de la Empresa en relación al giro del negocio.
A17: ¿ | B17: 2 | C17: Escrituras Públicas -Pedir Acta de Futuro Aumento de Capital.
A18: ¿ | B18: 3 | C18: Nómina de Accionistas y Administradores, para revisar las actas del aspecto societario.
A19: ¿ | B19: 4 | C19: Certificaciones (ISO-C.C.O-IESS)
A20: ¿ | B20: 5 | C20: Contrato de Arrendamiento (si fuera el caso)
A21: ¿¿ | B21: 6 | C21: Solicitar o bajar de la Superintendencia el RUP (Sistema Nacional de Contratación Publica) Registro Único de Proveedores.
A22: ¿¿ | B22: 7 | C22: Revisar y Verificar el Nombramiento del Presidente y del Gerente de la Empresa.(Sean estos Nacionales o Internacionales)
A23: ¿ | B23: 8 | C23: LUAE (Licencia Metropolitana Única para el ejercicio de las actividades económicas. (Si fuera el Caso)
A24: ¿¿ | B24: 9 | C24: Informes de Auditorias del Año Anterior, (Auditoria Externa, Auditoria de Salud-Auditoria Ambiental entre otras dependiendo el caso) Informe de Gerente.
A25: ¿¿ | B25: 10 | C25: Solicitar el Organigrama de la Empresa ( En caso de que no le entreguen el documento solicitado redactar y realizar el organigrama según lo observado en la empresa)
A26: ¿¿¿ | B26: 11 | C26: Manual de Políticas, Procedimientos y Descripción de Funciones por Departamento o Cargos dependiendo la empresa. (En caso de que no le entreguen el documento solicitado redactar y realizar las funciones que realiza el personal según el giro del negocio incluyendo el nombre del responsable del área)
A27: ¿¿ | B27: 12 | C27: Verificar que la empresa cuente con los cuatro libros Societarios, 1.- Libro de Actas. 2.- Libro de Expedientes. 3.- Libro de Certificado de Aportaciones. 4.- Libro de Participaciones o Libro de Acciones y Accionistas.
... A30: ¿¿ | B30: 15 | C30: Revisar y Analizar que el Libro De Participaciones O Libro De Acciones Y Accionistas cumpla con todo lo dispuesto por la ley de la Superintendencia de Compañías. (VER ANEXO)
B31: 16 | C31: Solicitar los contratos importantes celebrados por la compañía y vigentes en el periodo.
B32: 17 | C32: Solicitar contrato de Asesores Legales o Tributarios.
B33: 18 | C33: Solicitar el permiso de Funcionamiento de la compañía, o impuesto predial.
B34: 19 | C34: Solicitar el CALCULO ACTUARIAL
B35: 20 | C35: Acta de Aprobación y Contratación de Auditoria Externa
C36: CONTROL DEL MINISTERIO DE RELACIONES LABORALES
B37: 21 | C37: Solicitar Reglamento Interno - Reglamento de seguridad y salud
B38: 22 | C38: Verificar que exista el Reglamento Interno de Contratación de trabajadores aprobado por el MRL.
B39: 23 | C39: Solicitar carpeta de Contratos, Beneficios, entre Otros (VER ANEXO)
C40: CONTROL Y SISTEMA CONTABLE
B41: 24 | C41: Políticas Contables
B42: 25 | C42: Manual de Funciones del Sistema Contable
B43: 26 | C43: Solicitar el plan de Cuentas.
...

Sheet ANEXOS
A1: CONTENIDOS
A2: LIBROS SOCIETARIOS
A3: 1.- LIBRO DE ACTAS / 2.- LIBRO DE EXPEDINETES.
A4: 3.- LIBRO DE CERTIFICADO DE APORTACIONES.
A5: 4.- LIBRO DE PARTICIPACIONES O LIBRO DE ACCIONES y ACCIONISTAS:
A7: ANEXO 1
A8: LIBROS SOCIETARIOS
A11: Con respecto al Aspecto Societario la compañía debe presentar los siguientes Libros Societarios descritos a continuación:
A13: 1. Libro de Actas
A15: 2. Libro de Expedientes
A17: 3. Certificado de Aportaciones
A19: 4. Libro de Participaciones
... A44: Según El Reglamento De Juntas Generales De Socios Y Accionistas De Compañías.
A46: Art. 41.- Formas de llevar las actas.- Las actas de las juntas generales o asamblea de accionistas se llevarán en un libro especial destinado para el efecto, de forma física o digital. Cuando se trate de un libro físico, se asentarán en hojas foliadas a número seguido, escritas en el anverso y en el reverso, en las cuales, las actas figurarán una a continuación de otra, en riguroso orden cronológico, sin dejar espacios en blanco en su texto. Cuando se trate de un libro digital, se implementarán herramientas tecnológicas como el blockchain, siempre y cuando la información se encuentre organizada en una cadena de bloques o en cualquier otra red de distribución de datos o tecnología de registro y archivo de información virtual, segura y verificable. | C46: ANTERIOR EN ART. 34
A49: Art. 42.- Contenido del Expediente.- De cada junta o asamblea se formará un expediente que contendrá:
A50: a) La notificación dispuesta en el artículo 2 de este reglamento; y, la hoja del periódico en que conste la publicación de la convocatoria cuando fuere del caso, o el documento que pruebe que la convocatoria además se hizo en la forma complementaria que hubiere previsto el estatuto;
A51: b) Copias de las convocatorias dirigidas a los comisarios u órganos de fiscalización, si fuere del caso, citándolos a la junta o asamblea;
A52: c) La lista de los asistentes con la determinación de las participaciones o acciones que representen y, en este último caso, el valor pagado por ellas y los votos que le corresponda; así como, la forma de comparecencia acorde a lo previsto en los artículos 23, 24 y 25 del presente reglamento.
A53: d) Los nombramientos y poderes de representación entregados para actuar en la junta o asamblea.
A54: e) Copia del acta certificada por el Secretario de la junta o asamblea dando fe de que el documento es fiel copia del original.
A55: f) Los demás documentos que hubieren sido conocidos por la junta o asamblea.
A58: Art. 43.- Grabacion de las sesiones de junta general o asamblea de accionistas.- Todas las sesiones de las juntas generales o asambleas de socios o accionistas, deberán grabarse en soporte magnético o digital y es responsabilidad del Secretario de la junta o asamblea, incorporar el archivo informático al respectivo expediente. No será obligatoria la grabación magnetofónica o digital cuando se trate de juntas o asambleas universales, salvo que un accionista lo solicitare de manera expresa. Cuando se trate de socios o accionistas extranjeros, se podrán implementar medios que permitan la traducción simultánea de las intervenciones de la junta o asamblea, cuando se considere conveniente.
A60: Según la Ley de Superintendencia de Compañías.
A62: Art. 122: El acta de las deliberaciones y acuerdos de las juntas generales llevará las firmas del presidente y del secretario de la junta.
A63: … Las actas podrán extenderse a máquina, en hojas debidamente foliadas, o ser asentadas en un libro destinado para el efecto.
A65: El Libro de Actas deberá especificar contener, entre otro los siguientes parámetros:
... A84: Según El Reglamento De Juntas Generales De Socios Y Accionistas De Compañías.
A86: Art. 43.-Grabación de las sesiones de junta general.- Todas las sesiones de las juntas generales de socios o accionistas, deberán grabarse en soporte magnético o digital y es responsabilidad del Secretario de la junta incorporar el archivo informático al respectivo expediente. | C86: antes art. 36
A89: 3.- LIBRO DE CERTIFICADO DE APORTACIONES.
A91: Art. 176.- Los títulos de acción estarán escritos en idioma castellano y contendrán las siguientes declaraciones:
A92: 1. El nombre y domicilio principal de la compañía;
A93: 2. La cifra representativa del capital autorizado, capital suscrito y el número de acciones en que se divide el capital suscrito
A94: 3. El número de orden de la acción y del título, si éste representa varias acciones, y la clase a que pertenece;
A95: 4. La fecha de la escritura de constitución de la compañía, la notaría en la que se la otorgó y la fecha de inscripción en el Registro Mercantil, con la indicación del tomo, folio y número;
A96: 5. La indicación del nombre del propietario de las acciones
A97: 6. Si la acción es ordinaria o preferida y, en este caso, el objeto de la preferencia
A98: 8. La firma de la persona o personas autorizadas.
A100: Art 177 “Los títulos y certificados de acciones se extenderán en libros talonarios correlativamente numerados. Entregado el título o el certificado al accionista, éste suscribirá el correspondiente talonario. Los títulos y certificados nominativos se inscribirán, además, en el Libro de Acciones y Accionistas, en el que se anotarán las sucesivas transferencias, la constitución de derechos reales y las demás modificaciones que ocurran respecto al derecho sobre las acciones”
A102: Art 181… Los certificados deberán ser puestos a disposición de los accionistas que consten en el libro de acciones y accionistas dentro de los quince días hábiles siguientes a la fecha del acuerdo de aumento de capital.
A105: 4.- LIBRO DE PARTICIPACIONES O LIBRO DE ACCIONES Y ACCIONISTAS:
...
