Workbook

Sheet P-600
D1: 3 ANG ADMINISTRACIÓN DE NEGOCIOS GERENCIALES CÍA LTDA.
D2: PROGRAMA DE AUDITORÍA SOBRE LOS ESTADOS FINANCIEROS | Q2: P-600
P3: REF P.T
B4: CLIENTE: | D4: ABC
B5: PERIODO: | D5: Desde el 01 de enero al 31 de Diciembre del 2023 | H5: Preliminar: | M5: Final
B6: ÁREA | D6: INGRESOS - VENTAS | H6: (x) | N6: Aprobado | Q6: Firma y sello
B7: ELABORADO POR: | D7: Elizabeth Palacios | E7: FECHA: | H7: 45162 | L7: 45162 | Q7: R.C
B8: REVISADO POR: | D8: Roy Cisneros | E8: FECHA: | H8: =+H7+20 -> 45182 | L8: =+L7+1 -> 45163
A9: 1 | B9: OBJETIVOS: | D9: Determinación de la autenticidad de las ventas que se presentan en el Estado de Resultados.
D10: Las ventas están debidamente registradas por su importe y cuentan en los registros financieros correspondientes
A11: 111 | D11: Verificación de la valuación de los ingresos obtenidos o servicios prestados, en función de los activos y pasivos que modifican; Verificación de que los costos registrados correspondan a los ingresos obtenidos.Verificación de la inclusión en el Estado de Resultados, de la totalidad de los resultados obtenidos en el período correspondiente.
D12: REFERENCIAS
B13: ASEVERACIÓN: | I13: REVISIÓN | N13: TIPO DE PRUEBA
B14: E | C14: Existencia u ocurrencia | D14: V Valuacion | E14: ✓ | I14: Preliminar | N14: Pruebas Suntantivos.
B15: I | C15: Integridad o totalidad | D15: P Presentación y divulgación | I15: Final | M15: D | N15: . Pruebas Suntantivas de Detalle.
B16: D | C16: Derechos y obligaciones | D16: P1 Período | I16: Prel y Final | M16: A | N16: . Pruebas Suntantivas Analíticas
D17: C Clasificación | M17: C | N17: Pruebas de Control o Cumplimiento.
C19: PROCEDIMIENTOS | E19: ASEVERACIÓN | L19: REFERENCIA P. T | N19: PRUEBAS | Q19: REVISIÓN
E20: E | F20: I | G20: D | H20: V | I20: P | J20: P1 | K20: C | N20: D | O20: A | P20: C
C22: REALIZAR SUMARIA | L22: 600- | M22: 1
A23: 11 | C23: Actualice el memorando que describe el control interno existente en esta sección y concluya si es satisfactorio o no. | L23: 600-
A24: 1 | C24: Obtener un detalle de las ventas realizadas hasta la fecha de corte. | L24: 600-
A25: 111 | C25: Realice un cálculo global de ventas, para lo cual obtenga los movimientos en cantidades de los servicios prestados, determine su código, concepto, valor facturable en el período analizado. | L25: 600-
A26: 11 | C26: Realizar un corte documentario que incluya las ultimas y primeras facturas emitidas en el período anterior y el actual respectivamente.
A27: 11 | C27: Cotejar las ventas mensuales con el presupuesto de ingresos preparado por Gerencia. | L27: 600-
A28: 11 | C28: Comentar si la compañía incrementó sus ventas en relación con el período anterior, y explique por qué su variación. | L28: 600-
A29: 111 | C29: Realizar una prueba de acumulación de ingresos que consiste en efectuar una sumatoria de las facturas emitidas en los meses que mayor movimiento tenga dentro del período analizado. | L29: 600-
A30: 11 | C30: Coteje los resultados obtenidos contra registros contables, determine diferencias significativas y explique variaciones. | L30: 600-
C31: Elabore la cédula resumen de ventas y devoluciones por meses. | L31: 600-
C32: Explique variaciones entre meses. | L32: 600-
A33: 11 | C33: Partiendo de los créditos a los auxiliares de inventarios compruebe que estén amparados con documentos de embarque y que se facturaron al cliente. | L33: 600-
A34: 11 | C34: Si los créditos a inventarios se hacen por concentración, revisarla como enlace entre salidas y facturación. | L34: 600-
A35: 11 | C35: Cerciórese de que las facturas estén registradas correctamente en el libro o resumen de ventas. | L35: 600-
A36: 11 | C36: Compruebe precios de venta descuentos y condiciones contra pedidos y listas de precios de venta autorizados.
A37: 11 | C37: Compruebe la progresividad numérica de las facturas expedidas en un período. | L37: 600-
A38: 11 | C38: Identifique en las tiras de la máquina sumadora las facturas y las notas de crédito que seleccionó para las pruebas de procedimiento. | L38: 600-
A39: 11 | C39: Revisar que las facturas cancelas existan en el consecutivo fiscal, el original y todas sus copias anexas debidamente inutilizadas. | L39: 600-
A40: 1 | C40: Efectúe el corte de todas las formas numeradas relativas a los ingresos. | L40: 600-
A41: 1 | C41: Obtener un detalle de las ventas realizadas en los meses sujetos a revisión. | L41: 600-
A42: 11 | C42: Realizar una prueba de acumulación de ingresos que consiste en efectuar una sumatoria de las facturas emitidas, del mes de diciembre | L42: 600-
...

Sheet 600-1
C1: 3 A.N.G ADMINISTRACIÓN DE NEGOCIOS GERENCIALES CÍA. LTDA. | E1: 600-1
C2: REPORTE DIARIO DE TRABAJO
B3: FECHA: | C3: Preliminar: | D3: 45162
C4: Final: | D4: =+D3+100 -> 45262
B5: GUIA: | C5: Integro/Reintegro
B6: EMPRESA: | C6: XXXXX
B7: ELABORADO POR: | C7: K.B.
B8: REVISADO POR: | C8: E.P
B9: APROBADO POR: | C9: R.C.
B10: PERIODO : | C10: Desde el 01 de Enero 2023 al 31 de Diciembre del 2023
B11: ÁREA: | C11: (600) Ventas Netas
B12: MONTO DEL ÁREA: | C12: 100000
B13: CUENTA: | C13: CÓDIGO | D13: DESCRIPCIÓN | E13: VALOR
C14: 4.1.1. | D14: ventas 0% | E14: 70000
D15: ventas 12% | E15: 20000
B17: MONTO DE CUENTA: | C17: =SUM(E14:E16) -> 90000
B18: ALCANCE: | C18: =+C17/C12 -> 0.9
B19: MATERIALIDAD: | C19: 1
B20: RIESGO: | C20: ALTO:
C21: MEDIO: | D21: (X)
C22: BAJO:
B23: TIPO DE PRUEBA: | C23: Análisis, Cumplimiento y Sustantivas
B24: ASEVERACIÓN: | C24: Integridad y Exactitud
B25: TIEMPO ESTIMADO: | C25: 4 | E25: HORAS
A26: ¿¿ | B26: NARRATIVA DE LA PRUEBA | C26: Representan los ingresos prevenientes de las operaciones normales de la empresa por la enajenacion de bienes o srvicios, deducidos de las devoluciones recibidas y las rebajadas y descuentos concedidos sobre dichos ingresos
B27: NIA | C27: 530ni
A28: ¿¿ | B28: NOMBRE NIA | C28: MUESTREO DE AUDITORIA
A29: ¿¿¿ | B29: NIA PARRAFO: | C29: La norma internacional de auditoria 530 trata del uso del muestreo de auditoria estadístico y no estadístico cuando el auditor ha decidido usar muestreo de auditoria. Esto implica el diseño y selección de la muestra de auditoria, desarrollando pruebas de control y pruebas de detalle, evaluando los resultados de la muestra.
B30: PYMES, NIIF NIC: | C30: NIIF PYMES:
C31: NIIF FULL: | D31: (X)
B32: NORMA CONTAB. | C32: Sección 23 Ingresos de Actividades Ordinarias | E32: NIIF PYMES
A33: ¿¿¿¿¿¿ | B33: DETALLE SECCIÓN: | C33: Esta Sección se aplicará al contabilizar ingresos de actividades ordinarias procedentes de las siguientes transacciones y sucesos: (a) La venta de bienes (si los produce o no la entidad para su venta o los adquiere para su reventa). (b) La prestación de servicios. (c) Los contratos de construcción en los que la entidad es el contratista. (d) El uso, por parte de terceros, de activos de la entidad que produzcan intereses, regalías o dividendos.
B34: NORMA CONTAB. | C34: NIIF 15 INGRESOS DE ACTIVIDADES ORDINARIAS | E34: NIIF COMPLETAS
A35: ¿¿¿¿¿¿ | B35: DETALLE NIIF: | C35: Los ingresos de actividades ordinarias procedentes de la venta de bienes deben ser reconocidos y registrados en los estados financieros cuando se cumplen todas y cada una de las siguientes condiciones: (a) la entidad ha transferido al comprador los riesgos y ventajas, de tipo significativo, derivados de la propiedad de los bienes; (b) la entidad no conserva para sí ninguna implicación en la gestión corriente de los bienes vendidos, en el grado usualmente asociado con la propiedad, ni retiene el control efectivo sobre los mismos;

Sheet 601 mayor

Sheet 601 Ingresos
C1: PAPELES DE TRABAJO 3 A.N.G CIA. LTDA.
C2: empresa ***
C3: PT AL 31 DE DICIEMBRE DEL 2023
C4: MOVIMIENTO DE VENTAS
A6: ELABORADO POR | C6: K.B | F6: FECHA | G6: 45163
A7: REVISADO POR | C7: E.P. | F7: FECHA | G7: =3+G6 -> 45166
A10: MES | B10: Venta de bienes | D10: Otros ingresos de actividades ordinarias | F10: (-)Descuentos en ventas | H10: TOTAL
B11: 4.1.01 | D11: 4.1.08 | F11: 4.1.09
B12: DEBE | C12: HABER | D12: DEBE | E12: HABER | F12: DEBE | G12: HABER | I12: VENTAS B. | J12: OTROS ING.
A13: ENERO | F13: 0 | H13: =+G13+E13+C13-B13-D13-F13 -> 0 | I13: =+C13-B13 -> 0 | J13: =+E13-D13 -> 0
A14: FEBRERO | H14: =+G14+E14+C14-B14-D14-F14 -> 0 | I14: =+C14-B14 -> 0 | J14: =+E14-D14 -> 0
A15: MARZO | H15: =+G15+E15+C15-B15-D15-F15 -> 0 | I15: =+C15-B15 -> 0 | J15: =+E15-D15 -> 0
A16: ABRIL | H16: =+G16+E16+C16-B16-D16-F16 -> 0 | I16: =+C16-B16 -> 0 | J16: =+E16-D16 -> 0
A17: MAYO | H17: =+G17+E17+C17-B17-D17-F17 -> 0 | I17: =+C17-B17 -> 0 | J17: =+E17-D17 -> 0
A18: JUNIO | H18: =+G18+E18+C18-B18-D18-F18 -> 0 | I18: =+C18-B18 -> 0 | J18: =+E18-D18 -> 0
A19: JULIO | H19: =+G19+E19+C19-B19-D19-F19 -> 0 | I19: =+C19-B19 -> 0 | J19: =+E19-D19 -> 0
A20: AGOSTO | H20: =+G20+E20+C20-B20-D20-F20 -> 0 | I20: =+C20-B20 -> 0 | J20: =+E20-D20 -> 0
A21: SEPTIEMBRE | H21: =+G21+E21+C21-B21-D21-F21 -> 0 | I21: =+C21-B21 -> 0 | J21: =+E21-D21 -> 0
A22: OCTUBRE | H22: =+G22+E22+C22-B22-D22-F22 -> 0 | I22: =+C22-B22 -> 0 | J22: =+E22-D22 -> 0
A23: NOVIEMBRE | H23: =+G23+E23+C23-B23-D23-F23 -> 0 | I23: =+C23-B23 -> 0 | J23: =+E23-D23 -> 0
A24: DICIEMBRE | H24: =+G24+E24+C24-B24-D24-F24 -> 0 | I24: =+C24-B24 -> 0 | J24: =+E24-D24 -> 0
B25: =SUM(B13:B24) -> 0 | C25: =SUM(C13:C24) -> 0 | D25: =SUM(D13:D24) -> 0 | E25: =SUM(E13:E24) -> 0 | F25: =SUM(F13:F24) -> 0 | G25: =SUM(G13:G24) -> 0 | H25: =SUM(H13:H24) -> 0
C26: =+C25-B25 -> 0 | E26: =+E25-D25 -> 0 | G26: =+G25-F25 -> 0
A27: Balances
A28: Diferencia | C28: =+C26-C27 -> 0 | E28: =+E26-E27 -> 0 | G28: =+G26-G27 -> 0 | H28: =+H25-H27 -> 0

Sheet 601 Comp impuestos
A2: =+'601 Ingresos'!C2 -> empresa ***
A4: COMPROBACION DE PAGO DE IMPUESTO
A6: LIBROS CONTABLES VS DECLARACION
A8: MESES | B8: TOTAL INGRESOS DEL MAYOR | D8: según declaracion formul 104 (419) | E8: ingresos por reembolsos intermediarios (informativos) (434) | F8: DIFERENCIA | G8: VENTAS SEGÚN REPORTES(NO MAYORES) | H8: DIFERENCIA
B9: INGRESOS | C9: OTROS ING (N/C) | D9: Declarado
A10: ENERO | B10: =+'601 Ingresos'!I13 -> 0 | C10: 0 | E10: 0 | F10: =+B10+C10-D10 -> 0 | H10: =+B10-G10 -> 0
A11: FEBRERO | B11: =+'601 Ingresos'!I14 -> 0 | C11: 0 | E11: 0 | F11: =+B11+C11-D11-E11 -> 0 | H11: =+B11-G11 -> 0
A12: MARZO | B12: =+'601 Ingresos'!I15 -> 0 | C12: 0 | E12: 0 | F12: =+B12+C12-D12-E12 -> 0 | H12: =+B12-G12 -> 0
A13: ABRIL | B13: =+'601 Ingresos'!I16 -> 0 | C13: 0 | E13: 0 | F13: =+B13+C13-D13-E13 -> 0 | H13: =+B13-G13 -> 0
A14: MAYO | B14: =+'601 Ingresos'!I17 -> 0 | C14: 0 | E14: 0 | F14: =+B14+C14-D14-E14 -> 0 | H14: =+B14-G14 -> 0
A15: JUNIO | B15: =+'601 Ingresos'!I18 -> 0 | C15: 0 | E15: 0 | F15: =+B15+C15-D15-E15 -> 0 | H15: =+B15-G15 -> 0
A16: JULIO | B16: =+'601 Ingresos'!I19 -> 0 | C16: 0 | E16: 0 | F16: =+B16+C16-D16-E16 -> 0 | H16: =+B16-G16 -> 0
A17: AGOSTO | B17: =+'601 Ingresos'!I20 -> 0 | C17: 0 | E17: 0 | F17: =+B17+C17-D17-E17 -> 0 | H17: =+B17-G17 -> 0
A18: SEPTIEMBRE | B18: =+'601 Ingresos'!I21 -> 0 | C18: 0 | E18: 0 | F18: =+B18+C18-D18-E18 -> 0 | H18: =+B18-G18 -> 0
A19: OCTUBRE | B19: =+'601 Ingresos'!I22 -> 0 | C19: 0 | F19: =+B19+C19-D19-E19 -> 0 | H19: =+B19-G19 -> 0
A20: NOVIEMBRE | B20: =+'601 Ingresos'!I23 -> 0 | C20: 0 | F20: =+B20+C20-D20 -> 0 | H20: =+B20-G20 -> 0
A21: DICIEMBRE | B21: =+'601 Ingresos'!I24 -> 0 | C21: 0 | F21: =+B21+C21-D21 -> 0 | H21: =+B21-G21 -> 0
B22: =SUM(B10:B21) -> 0 | C22: =SUM(C10:C21) -> 0 | D22: =SUM(D10:D21) -> 0 | E22: =SUM(E10:E21) -> 0 | F22: =SUM(F10:F21) -> 0 | G22: =SUM(G10:G21) -> 0 | H22: =SUM(H10:H21) -> 0
D23: 0
A24: NOTA
A25: mediante el proceso de revicion al area de ingresos comparados con libros mayores se observo que la cuenta 4.1.01.01. de $945,427.46 no cuentan con diarios en el mayor.

Sheet 601 anexo con declaraciones
A1: PAPELES DE TRABAJO 3 A.N.G ADMINISTRACION DE NEGOCIOS GERENCIALES CIA. LTDA.
A2: =+'601 Ingresos'!C2 -> empresa ***
A3: 01 ENERO 2023 al 31 de DICIEMBRE Del 2023
A4: Comparativo anexos con declaraciones
B6: VENTAS
B7: SEGÚN DECLARACIONES | C7: VENTAS 0% ANEXO TL. RESUMEN EXPORTACIONES | D7: DIFERENCIA
A8: ENERO | B8: =+'601 Comp impuestos'!D10 -> 0 | D8: =+B8-C8 -> 0
A9: FEBRERO | B9: =+'601 Comp impuestos'!D11 -> 0 | D9: =+B9-C9 -> 0
A10: MARZO | B10: =+'601 Comp impuestos'!D12 -> 0 | D10: =+B10-C10 -> 0
A11: ABRIL | B11: =+'601 Comp impuestos'!D13 -> 0 | D11: =+B11-C11 -> 0
A12: MAYO | B12: =+'601 Comp impuestos'!D14 -> 0 | D12: =+B12-C12 -> 0
A13: JUNIO | B13: =+'601 Comp impuestos'!D15 -> 0 | D13: =+B13-C13 -> 0
A14: JULIO | B14: =+'601 Comp impuestos'!D16 -> 0 | D14: =+B14-C14 -> 0
A15: AGOSTO | B15: =+'601 Comp impuestos'!D17 -> 0 | D15: =+B15-C15 -> 0
A16: SEPTIEMBRE | B16: =+'601 Comp impuestos'!D18 -> 0 | D16: =+B16-C16 -> 0
A17: OCTUBRE | B17: =+'601 Comp impuestos'!D19 -> 0 | D17: =+B17-C17 -> 0
A18: NOVIEMBRE | B18: =+'601 Comp impuestos'!D20 -> 0 | D18: =+B18-C18 -> 0
A19: DICIEMBRE | B19: =+'601 Comp impuestos'!D21 -> 0 | D19: =+B19-C19 -> 0
B20: =SUM(B8:B19) -> 0 | C20: =SUM(C8:C19) -> 0 | D20: =SUM(D8:D19) -> 0
B24: Resolución n° NAC-DGERCGC16-00000096
B25: Art.2 Información sustentada en comprobantes electronicos que no deben ser reportados en el Anexos Transaccional Simplificado (ATS)
B26: Los sujetos pasivos que sean emisores de comprobantes de venta, retención y documentos complementarios bajo la modalidad electronica, SIEMPRE QUE IMPLEMENTEN EN SUS SISTEMAS LA VERSION DE TALES COMPROBANTES ELECTRONICOS, conforme a los requisitos adicionales de unicidad y especificaciones detalladas en los archivos "XML" y "XDS". que el Servicio de Rentas Internas publique en la ficha tecnica "version ATS" en la pagina WEB, no deberan registrar exclusivamente en los modulos compras y ventas de Anexo (ATS) la información que conste en dichos comprobantes electronicos
I29: .

Sheet 601 Reporte de venta
