Workbook

Sheet 111-1
C1: 3 A.N.G ADMINISTRACIÓN DE NEGOCIOS GERENCIALES CÍA. LTDA. | E1: 111-1
C2: REPORTE DIARIO DE TRABAJO
B3: FECHA: | C3: Preliminar: | D3: 45162
C4: Final: | D4: =+D3+100 -> 45262
B5: GUIA: | C5: Integro/Reintegro
B6: EMPRESA: | C6: XXXXX
B7: ELABORADO POR: | C7: K.B.
B8: REVISADO POR: | C8: E.P.
B9: APROBADO POR: | C9: R.C.
B10: PERIODO : | C10: Desde el 01 de Enero 2023 al 31 de Diciembre del 2023
B11: ÁREA: | C11: (111) Activos Fijos
B12: MONTO DEL ÁREA: | C12: 100000
B13: CUENTA: | C13: CÓDIGO | D13: DESCRIPCIÓN | E13: VALOR
C14: 1.2.1.2 | D14: Propiedad Planta y Equipos | E14: 100000
E15: 0
B17: MONTO DE CUENTA: | C17: =SUM(E14:E16) -> 100000
B18: ALCANCE: | C18: =+C17/C12 -> 1
B19: MATERIALIDAD: | C19: 1
B20: RIESGO: | C20: ALTO:
C21: MEDIO: | D21: (X)
C22: BAJO:
B23: TIPO DE PRUEBA: | C23: Análisis, Cumplimiento y Sustantivas
B24: ASEVERACIÓN: | C24: Integridad y Exactitud
B25: TIEMPO ESTIMADO: | C25: 4 | E25: HORAS
A26: ¿¿¿ | B26: NARRATIVA DE LA PRUEBA | C26: Proporcionar la evidencia objetiva de que las cantidades incluidas en el balance general son validas, genuinas y dignas de confianza y no simples estimaciones optimistas o conjeturas imaginarias.
B27: NIA | C27: 300
A28: ¿¿ | B28: NOMBRE NIA | C28: Planificación de la auditoría de estados financieros.
A29: ¿¿ | B29: NIA PARRAFO: | C29: El NIA es la normativa sobre la responsabilidad del auditor, de planificar la auditoría de estados financieros.Esta NIA está redactada en el contexto de auditorías recurrentes.Las consideraciones adicionales en un encargo de auditoría inicial figuran separadamente.
B30: PYMES, NIIF NIC: | C30: NIIF PYMES:
C31: NIIF FULL: | D31: (X)
B32: NORMA CONTAB. | C32: Sección No. 17 – Propiedades, Planta y Equipo | E32: NIIF PYMES
A33: ¿¿¿¿ | B33: DETALLE SECCIÓN: | C33: 17.1 Esta sección se aplicará a la contabilidad de las propiedades, planta y equipo, así como a las propiedades de inversión cuyo valor razonable no se pueda medir con fiabilidad sin costo o esfuerzo desproporcionado. La Sección 16 Propiedades de Inversión se aplicará a propiedades de inversión cuyo valor razonable se puede medir con fiabilidad sin costo o esfuerzo desproporcionado.
B34: NORMA CONTAB. | C34: NIC 16 - Propiedades, Planta y Equipo | E34: NIIF COMPLETAS
A35: ¿¿¿¿¿¿ | B35: DETALLE NIIF: | C35: El objetivo de esta Norma es prescribir el tratamiento contable de propiedades, planta y equipo, de forma que los usuarios de los estados financieros puedan conocer la información acerca de la inversión que la entidad tiene en sus propiedades, planta y equipo, así como los cambios que se hayan producido en dicha inversión. Los principales problemas que presenta el reconocimiento contable de propiedades, planta y equipo son la contabilización de los activos, la determinación de su importe en libros y los cargos por depreciación y pérdidas por deterioro que deben reconocerse con relación a los mismos.

Sheet P-111
D1: 3 ANG ADMINISTRACIÓN DE NEGOCIOS GERENCIALES CÍA LTDA.
D2: PROGRAMA DE AUDITORÍA SOBRE LOS ESTADOS FINANCIEROS | Q2: P-111
O3: REF P.T
B4: CLIENTE: | D4: ABC
B5: PERIODO: | D5: Desde el 01 de enero al 31 de Diciembre del 2023 | H5: Preliminar: | M5: Final
B6: ÁREA | D6: PROPIEDAD, PLANTA Y EQUIPO | H6: (x) | N6: Aprobado | Q6: Firma y sello
B7: ELABORADO POR: | D7: Elizabeth Palacios | E7: FECHA: | H7: 45162 | L7: 45162 | Q7: R.C
B8: REVISADO POR: | D8: Roy Cisneros | E8: FECHA: | H8: =+H7+20 -> 45182 | L8: =+L7+1 -> 45163
A9: 1 | B9: OBJETIVOS: | D9: Verificar su existencia física. Que la empresa posee físicamente y utilice en su propio beneficio los bienes registrados.
A10: 111 | D10: Que estén registrados al costo de adquisición efectivamente pagado. Verificar. Qué el método de depreciación utilizado sea adecuado y consistente con el utilizado en el ejercicio anterior. Autenticidad de la propiedad. Que los bienes registrados sean propiedad legal de la empresa, comprobados con Documentos
D11: REFERENCIAS
B12: ASEVERACIÓN: | I12: REVISIÓN | N12: TIPO DE PRUEBA
B13: E | C13: Existencia u ocurrencia | D13: V Valuacion | E13: ✓ | I13: Preliminar | N13: Pruebas Suntantivos.
B14: I | C14: Integridad o totalidad | D14: P Presentación y divulgación | I14: Final | M14: D | N14: . Pruebas Suntantivas de Detalle.
B15: D | C15: Derechos y obligaciones | D15: P1 Período | I15: Prel y Final | M15: A | N15: . Pruebas Suntantivas Analíticas
D16: C Clasificación | M16: C | N16: Pruebas de Control o Cumplimiento.
C18: PROCEDIMIENTOS | E18: ASEVERACIÓN | L18: REFERENCIA P. T | N18: PRUEBAS | Q18: REVISIÓN
E19: E | F19: I | G19: D | H19: V | I19: P | J19: P1 | K19: C | N19: D | O19: A | P19: C
C20: Realizar la Sumaria
C21: Realizar reporte diario | L21: 111- | M21: 1
C22: ACTIVO FIJO | L22: 111-
A23: 11 | C23: Verificar que los saldos iniciales de las cuentas del mayor auxiliar crucen con las cifras auditadas en el año anterior. | Q23: Prel y Final
A24: 111 | C24: Prepare un resumen del activo fijo, con los saldos de la depreciación acumulada con aquellos saldos de inicio del período, resumen que reflejará las adiciones y disminuciones existentes en el período de revisión. | L24: 111-
A25: 11 | C25: Realizar los respectivos cálculos de la depreciación y compare con los saldos presentados en el balance general. | L25: 111-
C26: Examinar las autorizaciones para las compras y ventas o retiros de propiedad y equipo: | L26: 111-
C27: . Actas de juntas
C28: . Asientos de diarios | L28: 111-
C29: . Facturas y documentos soportes | L29: 111-
A30: 111 | C30: Prepare un resumen del activo fijo, reconciliando el costo y los saldos de la depreciación acumulada con aquellos saldos de inicio del período, resumen que reflejará las adiciones y disminuciones existentes en el período de revisión. | L30: 111-
A31: 11 | C31: Revisar los gastos de depreciación, para determinar la razonabilidad tanto del cargo en el período como su correspondiente depreciación acumulada. | L31: 111-
A32: 11 | C32: Durante nuestra visita final, preguntar si existen propiedades, planta y equipo que estén prendados o dados en garantía. De haberlo, haga referencia crezada con el área de obligaciones. | L32: 111-
A33: 11 | C33: Determine la existencia de propiedades, planta y equipo que estén inactivas, totalmente depreciadas o que no estén siendo utilizadas en las operaciones de la compañía. | L33: 111-
A34: 111 | C34: Si se considera necesario, efectuar una inspección física del activo fijo para cerciorarse si un parte considerable de la planta y equipo esta permanentemente inútil, ha sido abandonado, o que no existe. | L34: 111-
A35: 11 | C35: Actualice el memorándum que describe el control interno existente en esta sección y concluya si es satisfactorio o no.
A36: 1 | C36: Solicite a la empresa, prepare una relación de altas y bajas de activo fijo en el formato estándar. | L36: 111-
A37: 11 | C37: Marcar con referencia de auditoria el reporte de Activos Fijos que es proporcionada por la compañía a la firma auditora. | L37: 111-
A38: 11 | C38: Examine las facturas del vendedor, documentos de importación y otros que amparen el costo de compra o fabricación. Obtenga fotocopia de las facturas. | L38: 111-
A39: 1 | C39: Examine la autorización para la venta o retiro. Actas, soportes | L39: 111-
A40: 11 | C40: Asegúrese de que el valor de costo, la depreciación acumulada y la correspondiente utilidad o pérdida fueron adecuadamente contabilizados. | L40: 111-
A41: 11 | C41: Actualice los activos fijos en el sistema de cálculos fiscales y líguelos vs. la balanza. (CUADRO ANEXO ICT) | L41: 111-
...

Sheet 111 Mov. activos fijos
B1: PAPELES DE TRABAJO LWG AUDITORES CIA. LTDA.
B2: EMPRESA *****
B3: A/T 31 DE DICIEMBRE DE 2023
B4: MOVIMIENTO DEL ACTIVO FIJO
B6: ELABORADO POR | C6: K.B | E6: FECHA | F6: 45163
B7: REVISADO POR | C7: E.P. | E7: FECHA | F7: =+F6+10 -> 45173
A11: CODIGO | B11: 10201010201001 | C11: 10201010301001 | D11: 10201010401001 | E11: 10201010601001 | F11: TOTAL | H11: PROPIEDADES DE INVERSION
A12: Detalle | B12: PLANTAS Y EQUIPOS | C12: MUEBLES Y ENSERES | D12: EQUIPO DE COMPUTACION | E12: VEHICULOS | H12: 10202010101001 | I12: 10202010101002 | J12: TOTAL
A13: saldo iniciales 31 de diciembre 2022 | F13: =SUM(B13:E13) -> 0 | H13: SKY BUILDING OFICINA 1026 | I13: PARQUEO P1-05
A14: adiciones compra vehiculo | F14: =SUM(B14:E14) -> 0 | J14: =SUM(H14:I14) -> 0
A15: adiciones - ajustes por NIIF | F15: =SUM(B15:E15) -> 0 | J15: =SUM(H15:I15) -> 0
A16: retiros venta vehiculo | F16: =SUM(B16:E16) -> 0 | J16: =SUM(H16:I16) -> 0
A17: Bajas | F17: =SUM(B17:E17) -> 0 | J17: =SUM(H17:I17) -> 0
A18: reclasificaciones | F18: =SUM(B18:E18) -> 0 | J18: =SUM(H18:I18) -> 0
A19: reversiones anulaciones | F19: =SUM(B19:E19) -> 0 | J19: =SUM(H19:I19) -> 0
F20: =SUM(B20:E20) -> 0 | J20: =SUM(H20:I20) -> 0
A21: Saldo Final 31 De Diciembre del 2023 | B21: =SUM(B13:B20) -> 0 | C21: =SUM(C13:C20) -> 0 | D21: =SUM(D13:D20) -> 0 | E21: =SUM(E13:E20) -> 0 | F21: =SUM(B21:E21) -> 0 | H21: =SUM(H14:H20) -> 0 | I21: =SUM(I14:I20) -> 0 | J21: =SUM(J14:J20) -> 0

Sheet 111 Deprec. Activos
B1: PAPELES DE TRABAJO LWG AUDITORES CIA. LTDA.
B2: =+'111 Mov. activos fijos'!B2 -> EMPRESA *****
B3: Del 01 de enero al 31 de diciembre del 2023
C5: MOVIMIENTO DE LA DEPRECIACIÓN
B7: ELABORADO POR: | C7: =+'111 Mov. activos fijos'!C6 -> K.B | E7: FECHA: | F7: =+'111 Mov. activos fijos'!F6 -> 45163
B8: REVISADO POR: | C8: =+'111 Mov. activos fijos'!C7 -> E.P. | E8: FECHA: | F8: =+F7+2 -> 45165
A12: CODIGO | B12: 10201010201002 | C12: 10201010301002 | D12: 10201010401002 | E12: 10201010601002 | F12: - | G12: TOTAL
A13: DETALLE | B13: PLANTAS Y EQUIPOS | C13: MUEBLES Y ENSERES | D13: EQUIPO DE COMPUTACION | E13: VEHICULOS
A14: =+'111 Mov. activos fijos'!A13 -> saldo iniciales 31 de diciembre 2022 | G14: =SUM(B14:F14) -> 0
A15: Dep. anual | G15: =SUM(B15:F15) -> 0
A16: Amorticacion Anual | G16: =SUM(B16:F16) -> 0
A17: retiros ventas | G17: =SUM(B17:F17) -> 0
A18: reclacificación | G18: =SUM(B18:F18) -> 0
A19: registrar activos fijos totalmente depreciados | G19: =SUM(B19:F19) -> 0
A20: reversiones anulaciones | G20: =SUM(B20:F20) -> 0
G21: =SUM(B21:F21) -> 0
A22: =+'111 Mov. activos fijos'!A21 -> Saldo Final 31 De Diciembre del 2023 | B22: =SUM(B14:B21) -> 0 | C22: =SUM(C14:C21) -> 0 | D22: =SUM(D14:D21) -> 0 | E22: =SUM(E14:E21) -> 0 | F22: =SUM(F14:F21) -> 0 | G22: =SUM(G14:G21) -> 0
B25: PRUEBA DE LA DEPRECIACIÓN | E25: SEGÚN AUDITORÍA MENSUAL | F25: DEP A AGOSTO | G25: Dep. Según PLAN B MAYOR | H25: DIFERENCIA
A26: =+'111 Mov. activos fijos'!B11 -> 10201010201001 | B26: =+'111 Mov. activos fijos'!B12 -> PLANTAS Y EQUIPOS | C26: =+'111 Mov. activos fijos'!B13 -> 0 | D26: 0.1 | E26: =+C26*D26/12 -> 0 | F26: =+E26*8 -> 0 | G26: =+B15 -> 0 | H26: =+F26-G26 -> 0
A27: =+'111 Mov. activos fijos'!C11 -> 10201010301001 | B27: =+'111 Mov. activos fijos'!C12 -> MUEBLES Y ENSERES | C27: =+'111 Mov. activos fijos'!C13 -> 0 | D27: 0.1 | E27: =+C27*D27/12 -> 0 | F27: =+E27*8 -> 0 | G27: =+C15 -> 0 | H27: =+F27-G27 -> 0
A28: =+'111 Mov. activos fijos'!D11 -> 10201010401001 | B28: =+'111 Mov. activos fijos'!D12 -> EQUIPO DE COMPUTACION | C28: =+'111 Mov. activos fijos'!D13 -> 0 | D28: 0.3333 | E28: =+C28*D28/12 -> 0 | F28: 0 | G28: =+D15 -> 0 | H28: =+F28-G28 -> 0
A29: =+'111 Mov. activos fijos'!E11 -> 10201010601001 | B29: =+'111 Mov. activos fijos'!E12 -> VEHICULOS | C29: =+'111 Mov. activos fijos'!E13 -> 0 | D29: 0.2 | E29: =+C29*D29/12 -> 0 | F29: =+E29*8 -> 0 | G29: =+E15 -> 0 | H29: =+F29-G29 -> 0
G30: =SUM(G26:G29) -> 0 | H30: =SUM(H26:H29) -> 0
F34: DEPRECIACION Y AMORTIZACION
E36: 50203012301001 | F36: Depreciacion Deducible
E37: 50203012301002 | F37: Depreciacion No Deducible
G38: =+G30-G36-G37 -> 0
